Workbook

Sheet 使用说明
A1: 内容数据库使用说明 | B1: 说明
A2: 文件用途 | B2: 本工作簿是“发现更多可能”页面的内容数据库。后续页面内容以此文件为准。
A3: 编辑顺序 | B3: 先维护“产品表”，再维护“场景表”，最后用“场景产品关系表”连接两者。
A4: 真实性原则 | B4: 所有“模拟待校准”内容仅用于演示。真实产品名称、客户、数据、图片和链接上线前必须核实。
A5: 多选分隔符 | B5: 行业、角色、标签、能力、步骤等多选字段统一使用全角竖线 ｜ 分隔。
A6: 推荐页取数 | B6: 场景表 + 场景产品关系表；上半部分取场景信息，下方左侧取场景说明，右侧取使用方法。
A7: 产品目录取数 | B7: 产品表；产品详情中的典型场景通过关系表反查。
A8: AI 提示词边界 | B8: AI 应用产品本身不展示提示词；参考提示词只存在于推荐场景与产品的关系记录中。
A9: 轻应用边界 | B9: 产品类型可为“轻应用”，但“目录是否展示”必须为“否”，只通过推荐场景出现。
A10: 图片填写 | B10: 可填写 HTTPS URL 或项目内相对路径。空白时页面使用默认视觉。
A11: 链接填写 | B11: 模板、解决方案填写真实目标链接；插件填写 PRD；轻应用填写搭建说明；AI 应用填写配置说明。
A12: 当前模拟规模 | B12: 推荐场景 18；AI 应用 12；插件 12；模板 12；解决方案 6；轻应用 6（仅推荐）。
A14: 数据统计 | B14: 数量
A15: 推荐场景 | B15: 18
A16: AI应用 | B16: 12
A17: 插件 | B17: 12
A18: 模板 | B18: 12
A19: 解决方案 | B19: 6
A20: 轻应用 | B20: 6
A21: 场景产品关系 | B21: 20

Sheet 案例录入表
A1: 案例ID | B1: 关联场景ID（可选） | C1: 场景名称 | D1: 原始场景描述 | E1: AI应用ID（可选） | F1: AI应用名称 | G1: 适用行业 | H1: 适用角色 | I1: 来源URL | J1: 真实性备注 | K1: 匹配状态
A2: CASE-0001 | B2: S001 | C2: 补全客户信息 | D2: 需求评审后，AI 自动从会议纪要、邮件中提取关键信息，一键回填到飞书项目字段，无需手动逐条录入。 | E2: A008 | F2: AI 智能填单 | G2: 互联网 | H2: 产品经理 | J2: 用户筛选 CSV 序号 1；图片：https://aka.doubaocdn.com/s/IMKcg667UN | K2: =IF(COUNTA(C2:D2,F2)=0,"",IF(B2="",IF(E2="",IF(F2="","待填AI应用","待建产品"),IF(COUNTIF('录入字典'!$C$2:$C$200,E2)=0,"AI应用ID无效",IF(F2="","补充AI应用名称",IF(F2<>VLOOKUP(E2,'录入字典'!$C$2:$D$200,2,FALSE),"AI应用名称与ID不一致","可同步")))),IF(COUNTIF('录入字典'!$A$2:$A$200,B2)=0,"场景ID无效",IF(C2<>VLOOKUP(B2,'录入字典'!$A$2:$B$200,2,FALSE),"场景名称与ID不一致",IF(E2="",IF(F2="","待填AI应用","待建产品"),IF(COUNTIF('录入字典'!$C$2:$C$200,E2)=0,"AI应用ID无效",IF(F2="","补充AI应用名称",IF(F2<>VLOOKUP(E2,'录入字典'!$C$2:$D$200,2,FALSE),"AI应用名称与ID不一致","可同步"))))))))
A3: CASE-0002 | B3: S002 | C3: 拆解会议任务 | D3: 需求评审会结束后，AI 自动提取所有待办项和决策要点，一键生成飞书项目子任务并关联到对应工作项，从讨论到执行无缝衔接。 | E3: A012 | F3: AI 智能会议分析 | G3: 互联网 | H3: 项目经理 | J3: 用户筛选 CSV 序号 2；图片：https://aka.doubaocdn.com/s/cqI7oo1jGy | K3: =IF(COUNTA(C3:D3,F3)=0,"",IF(B3="",IF(E3="",IF(F3="","待填AI应用","待建产品"),IF(COUNTIF('录入字典'!$C$2:$C$200,E3)=0,"AI应用ID无效",IF(F3="","补充AI应用名称",IF(F3<>VLOOKUP(E3,'录入字典'!$C$2:$D$200,2,FALSE),"AI应用名称与ID不一致","可同步")))),IF(COUNTIF('录入字典'!$A$2:$A$200,B3)=0,"场景ID无效",IF(C3<>VLOOKUP(B3,'录入字典'!$A$2:$B$200,2,FALSE),"场景名称与ID不一致",IF(E3="",IF(F3="","待填AI应用","待建产品"),IF(COUNTIF('录入字典'!$C$2:$C$200,E3)=0,"AI应用ID无效",IF(F3="","补充AI应用名称",IF(F3<>VLOOKUP(E3,'录入字典'!$C$2:$D$200,2,FALSE),"AI应用名称与ID不一致","可同步"))))))))
A4: CASE-0003 | B4: S003 | C4: 创建外部工单 | D4: 客服系统、邮件、飞书群中的用户反馈，AI 自动识别并创建为标准工单，无需人工逐个录入，大幅提升工单处理效率。 | E4: A013 | F4: AI 助手 | G4: 医疗 | H4: 运营 | J4: 用户筛选 CSV 序号 3；图片：https://aka.doubaocdn.com/s/OJkgxeTgKd | K4: =IF(COUNTA(C4:D4,F4)=0,"",IF(B4="",IF(E4="",IF(F4="","待填AI应用","待建产品"),IF(COUNTIF('录入字典'!$C$2:$C$200,E4)=0,"AI应用ID无效",IF(F4="","补充AI应用名称",IF(F4<>VLOOKUP(E4,'录入字典'!$C$2:$D$200,2,FALSE),"AI应用名称与ID不一致","可同步")))),IF(COUNTIF('录入字典'!$A$2:$A$200,B4)=0,"场景ID无效",IF(C4<>VLOOKUP(B4,'录入字典'!$A$2:$B$200,2,FALSE),"场景名称与ID不一致",IF(E4="",IF(F4="","待填AI应用","待建产品"),IF(COUNTIF('录入字典'!$C$2:$C$200,E4)=0,"AI应用ID无效",IF(F4="","补充AI应用名称",IF(F4<>VLOOKUP(E4,'录入字典'!$C$2:$D$200,2,FALSE),"AI应用名称与ID不一致","可同步"))))))))
A5: CASE-0004 | B5: S004 | C5: 创建邮件任务 | D5: 客户或合作方通过邮件提交的需求，AI 自动解析邮件内容并生成飞书项目工作项，避免遗漏重要邮件中的待办事项。 | E5: A013 | F5: AI 助手 | G5: 互联网 | H5: 产品经理 | J5: 用户筛选 CSV 序号 4；图片：https://aka.doubaocdn.com/s/bv0qSfwVgG | K5: =IF(COUNTA(C5:D5,F5)=0,"",IF(B5="",IF(E5="",IF(F5="","待填AI应用","待建产品"),IF(COUNTIF('录入字典'!$C$2:$C$200,E5)=0,"AI应用ID无效",IF(F5="","补充AI应用名称",IF(F5<>VLOOKUP(E5,'录入字典'!$C$2:$D$200,2,FALSE),"AI应用名称与ID不一致","可同步")))),IF(COUNTIF('录入字典'!$A$2:$A$200,B5)=0,"场景ID无效",IF(C5<>VLOOKUP(B5,'录入字典'!$A$2:$B$200,2,FALSE),"场景名称与ID不一致",IF(E5="",IF(F5="","待填AI应用","待建产品"),IF(COUNTIF('录入字典'!$C$2:$C$200,E5)=0,"AI应用ID无效",IF(F5="","补充AI应用名称",IF(F5<>VLOOKUP(E5,'录入字典'!$C$2:$D$200,2,FALSE),"AI应用名称与ID不一致","可同步"))))))))
A6: CASE-0005 | B6: S005 | C6: 提取合同条款 | D6: 上传合同文件后，AI 自动提取金额、期限、违约责任等关键条款，结构化录入到工作项字段，减少人工核对时间。 | E6: A013 | F6: AI 助手 | G6: 金融 | H6: 销售 | J6: 用户筛选 CSV 序号 5；图片：https://aka.doubaocdn.com/s/DJabXgkph8 | K6: =IF(COUNTA(C6:D6,F6)=0,"",IF(B6="",IF(E6="",IF(F6="","待填AI应用","待建产品"),IF(COUNTIF('录入字典'!$C$2:$C$200,E6)=0,"AI应用ID无效",IF(F6="","补充AI应用名称",IF(F6<>VLOOKUP(E6,'录入字典'!$C$2:$D$200,2,FALSE),"AI应用名称与ID不一致","可同步")))),IF(COUNTIF('录入字典'!$A$2:$A$200,B6)=0,"场景ID无效",IF(C6<>VLOOKUP(B6,'录入字典'!$A$2:$B$200,2,FALSE),"场景名称与ID不一致",IF(E6="",IF(F6="","待填AI应用","待建产品"),IF(COUNTIF('录入字典'!$C$2:$C$200,E6)=0,"AI应用ID无效",IF(F6="","补充AI应用名称",IF(F6<>VLOOKUP(E6,'录入字典'!$C$2:$D$200,2,FALSE),"AI应用名称与ID不一致","可同步"))))))))
A7: CASE-0006 | B7: S006 | C7: 分类客户反馈 | D7: 客服收到用户反馈后，AI 节点自动判断是 Bug、需求还是咨询，秒级路由到对应模块，减少人工分类和转派时间。 | E7: A013 | F7: AI 助手 | G7: 游戏 | H7: 运营 | J7: 用户筛选 CSV 序号 6；图片：https://aka.doubaocdn.com/s/OJkgxeTgKd | K7: =IF(COUNTA(C7:D7,F7)=0,"",IF(B7="",IF(E7="",IF(F7="","待填AI应用","待建产品"),IF(COUNTIF('录入字典'!$C$2:$C$200,E7)=0,"AI应用ID无效",IF(F7="","补充AI应用名称",IF(F7<>VLOOKUP(E7,'录入字典'!$C$2:$D$200,2,FALSE),"AI应用名称与ID不一致","可同步")))),IF(COUNTIF('录入字典'!$A$2:$A$200,B7)=0,"场景ID无效",IF(C7<>VLOOKUP(B7,'录入字典'!$A$2:$B$200,2,FALSE),"场景名称与ID不一致",IF(E7="",IF(F7="","待填AI应用","待建产品"),IF(COUNTIF('录入字典'!$C$2:$C$200,E7)=0,"AI应用ID无效",IF(F7="","补充AI应用名称",IF(F7<>VLOOKUP(E7,'录入字典'!$C$2:$D$200,2,FALSE),"AI应用名称与ID不一致","可同步"))))))))
A8: CASE-0007 | B8: S007 | C8: 分派研发需求 | D8: 新需求进入开发阶段时，AI 自动匹配最合适的开发人员，兼顾技能匹配度和当前工作负载，避免忙闲不均，减少人工派单时间。 | E8: A014 | F8: AI 智能分配 | G8: 互联网 | H8: 项目经理 | J8: 用户筛选 CSV 序号 7；图片：https://aka.doubaocdn.com/s/nvmVJKYDTY | K8: =IF(COUNTA(C8:D8,F8)=0,"",IF(B8="",IF(E8="",IF(F8="","待填AI应用","待建产品"),IF(COUNTIF('录入字典'!$C$2:$C$200,E8)=0,"AI应用ID无效",IF(F8="","补充AI应用名称",IF(F8<>VLOOKUP(E8,'录入字典'!$C$2:$D$200,2,FALSE),"AI应用名称与ID不一致","可同步")))),IF(COUNTIF('录入字典'!$A$2:$A$200,B8)=0,"场景ID无效",IF(C8<>VLOOKUP(B8,'录入字典'!$A$2:$B$200,2,FALSE),"场景名称与ID不一致",IF(E8="",IF(F8="","待填AI应用","待建产品"),IF(COUNTIF('录入字典'!$C$2:$C$200,E8)=0,"AI应用ID无效",IF(F8="","补充AI应用名称",IF(F8<>VLOOKUP(E8,'录入字典'!$C$2:$D$200,2,FALSE),"AI应用名称与ID不一致","可同步"))))))))
A9: CASE-0008 | B9: S008 | C9: 评定缺陷等级 | D9: 测试提交 Bug 后，AI 根据严重程度、影响范围和修复成本自动分级，并推荐对应的处理人，让缺陷管理更有条理。 | E9: A015 | F9: AI 缺陷分级 | G9: 游戏 | H9: 测试 | J9: 用户筛选 CSV 序号 8；图片：https://aka.doubaocdn.com/s/CvvUzmrizE | K9: =IF(COUNTA(C9:D9,F9)=0,"",IF(B9="",IF(E9="",IF(F9="","待填AI应用","待建产品"),IF(COUNTIF('录入字典'!$C$2:$C$200,E9)=0,"AI应用ID无效",IF(F9="","补充AI应用名称",IF(F9<>VLOOKUP(E9,'录入字典'!$C$2:$D$200,2,FALSE),"AI应用名称与ID不一致","可同步")))),IF(COUNTIF('录入字典'!$A$2:$A$200,B9)=0,"场景ID无效",IF(C9<>VLOOKUP(B9,'录入字典'!$A$2:$B$200,2,FALSE),"场景名称与ID不一致",IF(E9="",IF(F9="","待填AI应用","待建产品"),IF(COUNTIF('录入字典'!$C$2:$C$200,E9)=0,"AI应用ID无效",IF(F9="","补充AI应用名称",IF(F9<>VLOOKUP(E9,'录入字典'!$C$2:$D$200,2,FALSE),"AI应用名称与ID不一致","可同步"))))))))
A10: CASE-0009 | B10: S009 | C10: 分流客服工单 | D10: 电商平台的客服工单根据产品线、问题类型和用户等级自动分流到对应处理组，SLA 超时自动升级，确保每个工单都被及时处理。 | E10: A016 | F10: AI 工单分流 | G10: 零售 | H10: 运营 | J10: 用户筛选 CSV 序号 9；图片：https://aka.doubaocdn.com/s/RAu5lPDwZP | K10: =IF(COUNTA(C10:D10,F10)=0,"",IF(B10="",IF(E10="",IF(F10="","待填AI应用","待建产品"),IF(COUNTIF('录入字典'!$C$2:$C$200,E10)=0,"AI应用ID无效",IF(F10="","补充AI应用名称",IF(F10<>VLOOKUP(E10,'录入字典'!$C$2:$D$200,2,FALSE),"AI应用名称与ID不一致","可同步")))),IF(COUNTIF('录入字典'!$A$2:$A$200,B10)=0,"场景ID无效",IF(C10<>VLOOKUP(B10,'录入字典'!$A$2:$B$200,2,FALSE),"场景名称与ID不一致",IF(E10="",IF(F10="","待填AI应用","待建产品"),IF(COUNTIF('录入字典'!$C$2:$C$200,E10)=0,"AI应用ID无效",IF(F10="","补充AI应用名称",IF(F10<>VLOOKUP(E10,'录入字典'!$C$2:$D$200,2,FALSE),"AI应用名称与ID不一致","可同步"))))))))
A11: CASE-0010 | B11: S010 | C11: 检查交付质量 | D11: 提测节点中，AI 自动检查代码是否关联了需求、测试用例是否覆盖了验收标准，不符合的自动驳回并给出原因，让质量门禁真正生效。 | E11: A017 | F11: AI 质量检查 | G11: 互联网 | H11: 测试 | J11: 用户筛选 CSV 序号 10；图片：https://aka.doubaocdn.com/s/CvvUzmrizE | K11: =IF(COUNTA(C11:D11,F11)=0,"",IF(B11="",IF(E11="",IF(F11="","待填AI应用","待建产品"),IF(COUNTIF('录入字典'!$C$2:$C$200,E11)=0,"AI应用ID无效",IF(F11="","补充AI应用名称",IF(F11<>VLOOKUP(E11,'录入字典'!$C$2:$D$200,2,FALSE),"AI应用名称与ID不一致","可同步")))),IF(COUNTIF('录入字典'!$A$2:$A$200,B11)=0,"场景ID无效",IF(C11<>VLOOKUP(B11,'录入字典'!$A$2:$B$200,2,FALSE),"场景名称与ID不一致",IF(E11="",IF(F11="","待填AI应用","待建产品"),IF(COUNTIF('录入字典'!$C$2:$C$200,E11)=0,"AI应用ID无效",IF(F11="","补充AI应用名称",IF(F11<>VLOOKUP(E11,'录入字典'!$C$2:$D$200,2,FALSE),"AI应用名称与ID不一致","可同步"))))))))
A12: CASE-0011 | B12: S011 | C12: 检查需求合规 | D12: 需求提交审批前，AI 自动检查是否满足了合规要求：是否完成了风险评估、是否获得了法务审批、是否标注了数据安全等级。 | E12: A018 | F12: AI 合规审计 | G12: 金融 | H12: 高管 | J12: 用户筛选 CSV 序号 11；图片：https://aka.doubaocdn.com/s/DJabXgkph8 | K12: =IF(COUNTA(C12:D12,F12)=0,"",IF(B12="",IF(E12="",IF(F12="","待填AI应用","待建产品"),IF(COUNTIF('录入字典'!$C$2:$C$200,E12)=0,"AI应用ID无效",IF(F12="","补充AI应用名称",IF(F12<>VLOOKUP(E12,'录入字典'!$C$2:$D$200,2,FALSE),"AI应用名称与ID不一致","可同步")))),IF(COUNTIF('录入字典'!$A$2:$A$200,B12)=0,"场景ID无效",IF(C12<>VLOOKUP(B12,'录入字典'!$A$2:$B$200,2,FALSE),"场景名称与ID不一致",IF(E12="",IF(F12="","待填AI应用","待建产品"),IF(COUNTIF('录入字典'!$C$2:$C$200,E12)=0,"AI应用ID无效",IF(F12="","补充AI应用名称",IF(F12<>VLOOKUP(E12,'录入字典'!$C$2:$D$200,2,FALSE),"AI应用名称与ID不一致","可同步"))))))))
A13: CASE-0012 | B13: S012 | C13: 检查代码提交 | D13: 代码提交时，AI 自动检查是否关联了工作项、是否通过了 Code Review、是否包含必要的测试，不合规的提交自动拦截并通知开发者。 | E13: A019 | F13: AI 代码审查 | G13: 汽车 | H13: 研发 | J13: 用户筛选 CSV 序号 12；图片：https://aka.doubaocdn.com/s/a3S9pUgsCz | K13: =IF(COUNTA(C13:D13,F13)=0,"",IF(B13="",IF(E13="",IF(F13="","待填AI应用","待建产品"),IF(COUNTIF('录入字典'!$C$2:$C$200,E13)=0,"AI应用ID无效",IF(F13="","补充AI应用名称",IF(F13<>VLOOKUP(E13,'录入字典'!$C$2:$D$200,2,FALSE),"AI应用名称与ID不一致","可同步")))),IF(COUNTIF('录入字典'!$A$2:$A$200,B13)=0,"场景ID无效",IF(C13<>VLOOKUP(B13,'录入字典'!$A$2:$B$200,2,FALSE),"场景名称与ID不一致",IF(E13="",IF(F13="","待填AI应用","待建产品"),IF(COUNTIF('录入字典'!$C$2:$C$200,E13)=0,"AI应用ID无效",IF(F13="","补充AI应用名称",IF(F13<>VLOOKUP(E13,'录入字典'!$C$2:$D$200,2,FALSE),"AI应用名称与ID不一致","可同步"))))))))
... A36: CASE-0035 | B36: S041 | C36: 撰写产品手册 | D36: 版本验收后，AI 汇总功能说明、操作步骤和注意事项，生成面向用户的产品手册初稿。 | E36: A011 | F36: AI 生成云文档 | G36: 互联网｜消费电子｜教育 | H36: 产品经理｜运营 | J36: 用户指定新增场景；文案由助手整理。 | K36: =IF(COUNTA(C36:D36,F36)=0,"",IF(B36="",IF(E36="",IF(F36="","待填AI应用","待建产品"),IF(COUNTIF('录入字典'!$C$2:$C$200,E36)=0,"AI应用ID无效",IF(F36="","补充AI应用名称",IF(F36<>VLOOKUP(E36,'录入字典'!$C$2:$D$200,2,FALSE),"AI应用名称与ID不一致","可同步")))),IF(COUNTIF('录入字典'!$A$2:$A$200,B36)=0,"场景ID无效",IF(C36<>VLOOKUP(B36,'录入字典'!$A$2:$B$200,2,FALSE),"场景名称与ID不一致",IF(E36="",IF(F36="","待填AI应用","待建产品"),IF(COUNTIF('录入字典'!$C$2:$C$200,E36)=0,"AI应用ID无效",IF(F36="","补充AI应用名称",IF(F36<>VLOOKUP(E36,'录入字典'!$C$2:$D$200,2,FALSE),"AI应用名称与ID不一致","可同步"))))))))
A37: CASE-0036 | K37: =IF(COUNTA(C37:D37,F37)=0,"",IF(B37="",IF(E37="",IF(F37="","待填AI应用","待建产品"),IF(COUNTIF('录入字典'!$C$2:$C$200,E37)=0,"AI应用ID无效",IF(F37="","补充AI应用名称",IF(F37<>VLOOKUP(E37,'录入字典'!$C$2:$D$200,2,FALSE),"AI应用名称与ID不一致","可同步")))),IF(COUNTIF('录入字典'!$A$2:$A$200,B37)=0,"场景ID无效",IF(C37<>VLOOKUP(B37,'录入字典'!$A$2:$B$200,2,FALSE),"场景名称与ID不一致",IF(E37="",IF(F37="","待填AI应用","待建产品"),IF(COUNTIF('录入字典'!$C$2:$C$200,E37)=0,"AI应用ID无效",IF(F37="","补充AI应用名称",IF(F37<>VLOOKUP(E37,'录入字典'!$C$2:$D$200,2,FALSE),"AI应用名称与ID不一致","可同步"))))))))
A38: CASE-0037 | K38: =IF(COUNTA(C38:D38,F38)=0,"",IF(B38="",IF(E38="",IF(F38="","待填AI应用","待建产品"),IF(COUNTIF('录入字典'!$C$2:$C$200,E38)=0,"AI应用ID无效",IF(F38="","补充AI应用名称",IF(F38<>VLOOKUP(E38,'录入字典'!$C$2:$D$200,2,FALSE),"AI应用名称与ID不一致","可同步")))),IF(COUNTIF('录入字典'!$A$2:$A$200,B38)=0,"场景ID无效",IF(C38<>VLOOKUP(B38,'录入字典'!$A$2:$B$200,2,FALSE),"场景名称与ID不一致",IF(E38="",IF(F38="","待填AI应用","待建产品"),IF(COUNTIF('录入字典'!$C$2:$C$200,E38)=0,"AI应用ID无效",IF(F38="","补充AI应用名称",IF(F38<>VLOOKUP(E38,'录入字典'!$C$2:$D$200,2,FALSE),"AI应用名称与ID不一致","可同步"))))))))
A39: CASE-0038 | K39: =IF(COUNTA(C39:D39,F39)=0,"",IF(B39="",IF(E39="",IF(F39="","待填AI应用","待建产品"),IF(COUNTIF('录入字典'!$C$2:$C$200,E39)=0,"AI应用ID无效",IF(F39="","补充AI应用名称",IF(F39<>VLOOKUP(E39,'录入字典'!$C$2:$D$200,2,FALSE),"AI应用名称与ID不一致","可同步")))),IF(COUNTIF('录入字典'!$A$2:$A$200,B39)=0,"场景ID无效",IF(C39<>VLOOKUP(B39,'录入字典'!$A$2:$B$200,2,FALSE),"场景名称与ID不一致",IF(E39="",IF(F39="","待填AI应用","待建产品"),IF(COUNTIF('录入字典'!$C$2:$C$200,E39)=0,"AI应用ID无效",IF(F39="","补充AI应用名称",IF(F39<>VLOOKUP(E39,'录入字典'!$C$2:$D$200,2,FALSE),"AI应用名称与ID不一致","可同步"))))))))
A40: CASE-0039 | K40: =IF(COUNTA(C40:D40,F40)=0,"",IF(B40="",IF(E40="",IF(F40="","待填AI应用","待建产品"),IF(COUNTIF('录入字典'!$C$2:$C$200,E40)=0,"AI应用ID无效",IF(F40="","补充AI应用名称",IF(F40<>VLOOKUP(E40,'录入字典'!$C$2:$D$200,2,FALSE),"AI应用名称与ID不一致","可同步")))),IF(COUNTIF('录入字典'!$A$2:$A$200,B40)=0,"场景ID无效",IF(C40<>VLOOKUP(B40,'录入字典'!$A$2:$B$200,2,FALSE),"场景名称与ID不一致",IF(E40="",IF(F40="","待填AI应用","待建产品"),IF(COUNTIF('录入字典'!$C$2:$C$200,E40)=0,"AI应用ID无效",IF(F40="","补充AI应用名称",IF(F40<>VLOOKUP(E40,'录入字典'!$C$2:$D$200,2,FALSE),"AI应用名称与ID不一致","可同步"))))))))
A41: CASE-0040 | K41: =IF(COUNTA(C41:D41,F41)=0,"",IF(B41="",IF(E41="",IF(F41="","待填AI应用","待建产品"),IF(COUNTIF('录入字典'!$C$2:$C$200,E41)=0,"AI应用ID无效",IF(F41="","补充AI应用名称",IF(F41<>VLOOKUP(E41,'录入字典'!$C$2:$D$200,2,FALSE),"AI应用名称与ID不一致","可同步")))),IF(COUNTIF('录入字典'!$A$2:$A$200,B41)=0,"场景ID无效",IF(C41<>VLOOKUP(B41,'录入字典'!$A$2:$B$200,2,FALSE),"场景名称与ID不一致",IF(E41="",IF(F41="","待填AI应用","待建产品"),IF(COUNTIF('录入字典'!$C$2:$C$200,E41)=0,"AI应用ID无效",IF(F41="","补充AI应用名称",IF(F41<>VLOOKUP(E41,'录入字典'!$C$2:$D$200,2,FALSE),"AI应用名称与ID不一致","可同步"))))))))
A42: CASE-0041 | K42: =IF(COUNTA(C42:D42,F42)=0,"",IF(B42="",IF(E42="",IF(F42="","待填AI应用","待建产品"),IF(COUNTIF('录入字典'!$C$2:$C$200,E42)=0,"AI应用ID无效",IF(F42="","补充AI应用名称",IF(F42<>VLOOKUP(E42,'录入字典'!$C$2:$D$200,2,FALSE),"AI应用名称与ID不一致","可同步")))),IF(COUNTIF('录入字典'!$A$2:$A$200,B42)=0,"场景ID无效",IF(C42<>VLOOKUP(B42,'录入字典'!$A$2:$B$200,2,FALSE),"场景名称与ID不一致",IF(E42="",IF(F42="","待填AI应用","待建产品"),IF(COUNTIF('录入字典'!$C$2:$C$200,E42)=0,"AI应用ID无效",IF(F42="","补充AI应用名称",IF(F42<>VLOOKUP(E42,'录入字典'!$C$2:$D$200,2,FALSE),"AI应用名称与ID不一致","可同步"))))))))
A43: CASE-0042 | K43: =IF(COUNTA(C43:D43,F43)=0,"",IF(B43="",IF(E43="",IF(F43="","待填AI应用","待建产品"),IF(COUNTIF('录入字典'!$C$2:$C$200,E43)=0,"AI应用ID无效",IF(F43="","补充AI应用名称",IF(F43<>VLOOKUP(E43,'录入字典'!$C$2:$D$200,2,FALSE),"AI应用名称与ID不一致","可同步")))),IF(COUNTIF('录入字典'!$A$2:$A$200,B43)=0,"场景ID无效",IF(C43<>VLOOKUP(B43,'录入字典'!$A$2:$B$200,2,FALSE),"场景名称与ID不一致",IF(E43="",IF(F43="","待填AI应用","待建产品"),IF(COUNTIF('录入字典'!$C$2:$C$200,E43)=0,"AI应用ID无效",IF(F43="","补充AI应用名称",IF(F43<>VLOOKUP(E43,'录入字典'!$C$2:$D$200,2,FALSE),"AI应用名称与ID不一致","可同步"))))))))
A44: CASE-0043 | K44: =IF(COUNTA(C44:D44,F44)=0,"",IF(B44="",IF(E44="",IF(F44="","待填AI应用","待建产品"),IF(COUNTIF('录入字典'!$C$2:$C$200,E44)=0,"AI应用ID无效",IF(F44="","补充AI应用名称",IF(F44<>VLOOKUP(E44,'录入字典'!$C$2:$D$200,2,FALSE),"AI应用名称与ID不一致","可同步")))),IF(COUNTIF('录入字典'!$A$2:$A$200,B44)=0,"场景ID无效",IF(C44<>VLOOKUP(B44,'录入字典'!$A$2:$B$200,2,FALSE),"场景名称与ID不一致",IF(E44="",IF(F44="","待填AI应用","待建产品"),IF(COUNTIF('录入字典'!$C$2:$C$200,E44)=0,"AI应用ID无效",IF(F44="","补充AI应用名称",IF(F44<>VLOOKUP(E44,'录入字典'!$C$2:$D$200,2,FALSE),"AI应用名称与ID不一致","可同步"))))))))
A45: CASE-0044 | K45: =IF(COUNTA(C45:D45,F45)=0,"",IF(B45="",IF(E45="",IF(F45="","待填AI应用","待建产品"),IF(COUNTIF('录入字典'!$C$2:$C$200,E45)=0,"AI应用ID无效",IF(F45="","补充AI应用名称",IF(F45<>VLOOKUP(E45,'录入字典'!$C$2:$D$200,2,FALSE),"AI应用名称与ID不一致","可同步")))),IF(COUNTIF('录入字典'!$A$2:$A$200,B45)=0,"场景ID无效",IF(C45<>VLOOKUP(B45,'录入字典'!$A$2:$B$200,2,FALSE),"场景名称与ID不一致",IF(E45="",IF(F45="","待填AI应用","待建产品"),IF(COUNTIF('录入字典'!$C$2:$C$200,E45)=0,"AI应用ID无效",IF(F45="","补充AI应用名称",IF(F45<>VLOOKUP(E45,'录入字典'!$C$2:$D$200,2,FALSE),"AI应用名称与ID不一致","可同步"))))))))
A46: CASE-0045 | K46: =IF(COUNTA(C46:D46,F46)=0,"",IF(B46="",IF(E46="",IF(F46="","待填AI应用","待建产品"),IF(COUNTIF('录入字典'!$C$2:$C$200,E46)=0,"AI应用ID无效",IF(F46="","补充AI应用名称",IF(F46<>VLOOKUP(E46,'录入字典'!$C$2:$D$200,2,FALSE),"AI应用名称与ID不一致","可同步")))),IF(COUNTIF('录入字典'!$A$2:$A$200,B46)=0,"场景ID无效",IF(C46<>VLOOKUP(B46,'录入字典'!$A$2:$B$200,2,FALSE),"场景名称与ID不一致",IF(E46="",IF(F46="","待填AI应用","待建产品"),IF(COUNTIF('录入字典'!$C$2:$C$200,E46)=0,"AI应用ID无效",IF(F46="","补充AI应用名称",IF(F46<>VLOOKUP(E46,'录入字典'!$C$2:$D$200,2,FALSE),"AI应用名称与ID不一致","可同步"))))))))
A47: CASE-0046 | K47: =IF(COUNTA(C47:D47,F47)=0,"",IF(B47="",IF(E47="",IF(F47="","待填AI应用","待建产品"),IF(COUNTIF('录入字典'!$C$2:$C$200,E47)=0,"AI应用ID无效",IF(F47="","补充AI应用名称",IF(F47<>VLOOKUP(E47,'录入字典'!$C$2:$D$200,2,FALSE),"AI应用名称与ID不一致","可同步")))),IF(COUNTIF('录入字典'!$A$2:$A$200,B47)=0,"场景ID无效",IF(C47<>VLOOKUP(B47,'录入字典'!$A$2:$B$200,2,FALSE),"场景名称与ID不一致",IF(E47="",IF(F47="","待填AI应用","待建产品"),IF(COUNTIF('录入字典'!$C$2:$C$200,E47)=0,"AI应用ID无效",IF(F47="","补充AI应用名称",IF(F47<>VLOOKUP(E47,'录入字典'!$C$2:$D$200,2,FALSE),"AI应用名称与ID不一致","可同步"))))))))
A48: CASE-0047 | K48: =IF(COUNTA(C48:D48,F48)=0,"",IF(B48="",IF(E48="",IF(F48="","待填AI应用","待建产品"),IF(COUNTIF('录入字典'!$C$2:$C$200,E48)=0,"AI应用ID无效",IF(F48="","补充AI应用名称",IF(F48<>VLOOKUP(E48,'录入字典'!$C$2:$D$200,2,FALSE),"AI应用名称与ID不一致","可同步")))),IF(COUNTIF('录入字典'!$A$2:$A$200,B48)=0,"场景ID无效",IF(C48<>VLOOKUP(B48,'录入字典'!$A$2:$B$200,2,FALSE),"场景名称与ID不一致",IF(E48="",IF(F48="","待填AI应用","待建产品"),IF(COUNTIF('录入字典'!$C$2:$C$200,E48)=0,"AI应用ID无效",IF(F48="","补充AI应用名称",IF(F48<>VLOOKUP(E48,'录入字典'!$C$2:$D$200,2,FALSE),"AI应用名称与ID不一致","可同步"))))))))
... A201: CASE-0200 | K201: =IF(COUNTA(C201:D201,F201)=0,"",IF(B201="",IF(E201="",IF(F201="","待填AI应用","待建产品"),IF(COUNTIF('录入字典'!$C$2:$C$200,E201)=0,"AI应用ID无效",IF(F201="","补充AI应用名称",IF(F201<>VLOOKUP(E201,'录入字典'!$C$2:$D$200,2,FALSE),"AI应用名称与ID不一致","可同步")))),IF(COUNTIF('录入字典'!$A$2:$A$200,B201)=0,"场景ID无效",IF(C201<>VLOOKUP(B201,'录入字典'!$A$2:$B$200,2,FALSE),"场景名称与ID不一致",IF(E201="",IF(F201="","待填AI应用","待建产品"),IF(COUNTIF('录入字典'!$C$2:$C$200,E201)=0,"AI应用ID无效",IF(F201="","补充AI应用名称",IF(F201<>VLOOKUP(E201,'录入字典'!$C$2:$D$200,2,FALSE),"AI应用名称与ID不一致","可同步"))))))))

Sheet 场景表
A1: 场景ID | B1: 场景名称 | C1: 工作目标 | D1: 卡片短描述 | E1: 问题描述 | F1: 场景说明 | G1: 预期价值 | H1: 适用行业 | I1: 适用角色 | J1: 场景标签 | K1: 封面类型 | L1: 封面图片 | M1: 客户案例 | N1: 量化结果 | O1: 是否推荐 | P1: 推荐排序 | Q1: 内容状态 | R1: 真实性备注
A2: S001 | B2: 补全客户信息 | C2: 信息提取与补全 | D2: AI 节点自动从会议纪要、邮件中提取关键信息，一键回填到飞书项目字段，无需手动逐条录入。 | E2: 当前“补全客户信息”依赖人工读取材料、判断规则并执行后续操作，处理效率和结果一致性容易受个人经验影响。 | F2: 需求评审后，AI 节点自动从会议纪要、邮件中提取关键信息，一键回填到飞书项目字段，无需手动逐条录入。 | G2: 减少人工处理｜统一输出结构｜降低信息遗漏 | H2: 互联网 | I2: 产品经理 | J2: 信息提取｜自动回填 | K2: 流程节点 | L2: https://aka.doubaocdn.com/s/IMKcg667UN | O2: 是 | P2: 1 | Q2: 模拟待校准 | R2: 来源：用户筛选 CSV 序号 1；场景名称和描述已按流程节点口径整理。
A3: S002 | B3: 拆解会议任务 | C3: 计划拆解与协同 | D3: AI 节点自动提取所有待办项和决策要点，一键生成飞书项目子任务并关联到对应工作项，从讨论到执行无缝衔接。 | E3: 当前“拆解会议任务”依赖人工读取材料、判断规则并执行后续操作，处理效率和结果一致性容易受个人经验影响。 | F3: 需求评审会结束后，AI 节点自动提取所有待办项和决策要点，一键生成飞书项目子任务并关联到对应工作项，从讨论到执行无缝衔接。 | G3: 统一拆解口径｜减少遗漏｜加快进入执行 | H3: 互联网 | I3: 项目经理 | J3: 会议分析｜自动建单 | K3: 流程节点 | L3: https://aka.doubaocdn.com/s/cqI7oo1jGy | O3: 是 | P3: 2 | Q3: 模拟待校准 | R3: 来源：用户筛选 CSV 序号 2；场景名称和描述已按流程节点口径整理。
A4: S003 | B4: 创建外部工单 | C4: 分类分派与流转 | D4: 客服系统、邮件、飞书群中的用户反馈，AI 节点自动识别并创建为标准工单，无需人工逐个录入，大幅提升工单处理效率。 | E4: 当前“创建外部工单”依赖人工读取材料、判断规则并执行后续操作，处理效率和结果一致性容易受个人经验影响。 | F4: 客服系统、邮件、飞书群中的用户反馈，AI 节点自动识别并创建为标准工单，无需人工逐个录入，大幅提升工单处理效率。 | G4: 减少人工处理｜统一输出结构｜降低信息遗漏 | H4: 医疗 | I4: 运营 | J4: 工单识别｜自动建单 | K4: 流程节点 | L4: https://aka.doubaocdn.com/s/OJkgxeTgKd | O4: 是 | P4: 3 | Q4: 模拟待校准 | R4: 来源：用户筛选 CSV 序号 3；场景名称和描述已按流程节点口径整理。
A5: S004 | B5: 创建邮件任务 | C5: 计划拆解与协同 | D5: 客户或合作方通过邮件提交的需求，AI 节点自动解析邮件内容并生成飞书项目工作项，避免遗漏重要邮件中的待办事项。 | E5: 当前“创建邮件任务”依赖人工读取材料、判断规则并执行后续操作，处理效率和结果一致性容易受个人经验影响。 | F5: 客户或合作方通过邮件提交的需求，AI 节点自动解析邮件内容并生成飞书项目工作项，避免遗漏重要邮件中的待办事项。 | G5: 减少人工处理｜统一输出结构｜降低信息遗漏 | H5: 互联网 | I5: 产品经理 | J5: 邮件解析｜自动建单 | K5: 流程节点 | L5: https://aka.doubaocdn.com/s/bv0qSfwVgG | O5: 是 | P5: 4 | Q5: 模拟待校准 | R5: 来源：用户筛选 CSV 序号 4；场景名称和描述已按流程节点口径整理。
A6: S005 | B6: 提取合同条款 | C6: 信息提取与补全 | D6: AI 节点自动提取金额、期限、违约责任等关键条款，结构化录入到工作项字段，减少人工核对时间。 | E6: 当前“提取合同条款”依赖人工读取材料、判断规则并执行后续操作，处理效率和结果一致性容易受个人经验影响。 | F6: 上传合同文件后，AI 节点自动提取金额、期限、违约责任等关键条款，结构化录入到工作项字段，减少人工核对时间。 | G6: 减少人工处理｜统一输出结构｜降低信息遗漏 | H6: 金融 | I6: 销售 | J6: 合同解析｜条款提取 | K6: 流程节点 | L6: https://aka.doubaocdn.com/s/DJabXgkph8 | O6: 是 | P6: 5 | Q6: 模拟待校准 | R6: 来源：用户筛选 CSV 序号 5；场景名称和描述已按流程节点口径整理。
A7: S006 | B7: 分类客户反馈 | C7: 分类分派与流转 | D7: AI 节点自动判断是 Bug、需求还是咨询，秒级路由到对应模块，减少人工分类和转派时间。 | E7: 当前“分类客户反馈”依赖人工读取材料、判断规则并执行后续操作，处理效率和结果一致性容易受个人经验影响。 | F7: 客服收到用户反馈后，AI 节点自动判断是 Bug、需求还是咨询，秒级路由到对应模块，减少人工分类和转派时间。 | G7: 缩短流转时间｜提升判断一致性｜减少人工分派 | H7: 游戏 | I7: 运营 | J7: 语义分类｜自动路由 | K7: 流程节点 | L7: https://aka.doubaocdn.com/s/OJkgxeTgKd | O7: 是 | P7: 6 | Q7: 模拟待校准 | R7: 来源：用户筛选 CSV 序号 6；场景名称和描述已按流程节点口径整理。
A8: S007 | B8: 分派研发需求 | C8: 分类分派与流转 | D8: 新需求进入开发阶段时，AI 节点自动匹配最合适的开发人员，兼顾技能匹配度和当前工作负载，避免忙闲不均，减少人工派单时间。 | E8: 当前“分派研发需求”依赖人工读取材料、判断规则并执行后续操作，处理效率和结果一致性容易受个人经验影响。 | F8: 新需求进入开发阶段时，AI 节点自动匹配最合适的开发人员，兼顾技能匹配度和当前工作负载，避免忙闲不均，减少人工派单时间。 | G8: 缩短流转时间｜提升判断一致性｜减少人工分派 | H8: 互联网 | I8: 项目经理 | J8: 技能匹配｜负载均衡 | K8: 流程节点 | L8: https://aka.doubaocdn.com/s/nvmVJKYDTY | O8: 是 | P8: 7 | Q8: 模拟待校准 | R8: 来源：用户筛选 CSV 序号 7；场景名称和描述已按流程节点口径整理。
A9: S008 | B9: 评定缺陷等级 | C9: 质量检查与审核 | D9: 测试提交 Bug 后，AI 根据严重程度、影响范围和修复成本自动分级，并推荐对应的处理人。 | E9: 当前“评定缺陷等级”依赖人工读取材料、判断规则并执行后续操作，处理效率和结果一致性容易受个人经验影响。 | F9: 测试提交 Bug 后，AI 根据严重程度、影响范围和修复成本自动分级，并推荐对应的处理人。 | G9: 缩短流转时间｜提升判断一致性｜减少人工分派 | H9: 游戏 | I9: 测试 | J9: 严重度分级｜自动指派 | K9: 流程节点 | L9: https://aka.doubaocdn.com/s/CvvUzmrizE | O9: 是 | P9: 8 | Q9: 模拟待校准 | R9: 来源：用户筛选 CSV 序号 8；场景名称和描述已按流程节点口径整理。
A10: S009 | B10: 分流客服工单 | C10: 分类分派与流转 | D10: 电商平台的客服工单根据产品线、问题类型和用户等级自动分流到对应处理组，SLA 超时自动升级。 | E10: 当前“分流客服工单”依赖人工读取材料、判断规则并执行后续操作，处理效率和结果一致性容易受个人经验影响。 | F10: 电商平台的客服工单根据产品线、问题类型和用户等级自动分流到对应处理组，SLA 超时自动升级。 | G10: 缩短流转时间｜提升判断一致性｜减少人工分派 | H10: 零售 | I10: 运营 | J10: 多级分流｜SLA 管控 | K10: 流程节点 | L10: https://aka.doubaocdn.com/s/RAu5lPDwZP | O10: 是 | P10: 9 | Q10: 模拟待校准 | R10: 来源：用户筛选 CSV 序号 9；场景名称和描述已按流程节点口径整理。
A11: S010 | B11: 检查交付质量 | C11: 质量检查与审核 | D11: 提测节点中，AI 节点自动检查代码是否关联了需求、测试用例是否覆盖了验收标准，不符合的自动驳回并给出原因。 | E11: 当前“检查交付质量”依赖人工读取材料、判断规则并执行后续操作，处理效率和结果一致性容易受个人经验影响。 | F11: 提测节点中，AI 节点自动检查代码是否关联了需求、测试用例是否覆盖了验收标准，不符合的自动驳回并给出原因。 | G11: 前置发现问题｜统一审核标准｜降低合规风险 | H11: 互联网 | I11: 测试 | J11: 自动检查｜质量门禁 | K11: 流程节点 | L11: https://aka.doubaocdn.com/s/CvvUzmrizE | O11: 是 | P11: 10 | Q11: 模拟待校准 | R11: 来源：用户筛选 CSV 序号 10；场景名称和描述已按流程节点口径整理。
A12: S011 | B12: 检查需求合规 | C12: 质量检查与审核 | D12: 需求提交审批前，AI 节点自动检查是否满足了合规要求：是否完成了风险评估、是否获得了法务审批、是否标注了数据安全等级。 | E12: 当前“检查需求合规”依赖人工读取材料、判断规则并执行后续操作，处理效率和结果一致性容易受个人经验影响。 | F12: 需求提交审批前，AI 节点自动检查是否满足了合规要求：是否完成了风险评估、是否获得了法务审批、是否标注了数据安全等级。 | G12: 前置发现问题｜统一审核标准｜降低合规风险 | H12: 金融 | I12: 高管 | J12: 合规检查｜风险评估 | K12: 流程节点 | L12: https://aka.doubaocdn.com/s/DJabXgkph8 | O12: 是 | P12: 11 | Q12: 模拟待校准 | R12: 来源：用户筛选 CSV 序号 11；场景名称和描述已按流程节点口径整理。
A13: S012 | B13: 检查代码提交 | C13: 质量检查与审核 | D13: 代码提交时，AI 节点自动检查是否关联了工作项、是否通过了 Code Review、是否包含必要的测试，不合规的提交自动拦截并通知开发者。 | E13: 当前“检查代码提交”依赖人工读取材料、判断规则并执行后续操作，处理效率和结果一致性容易受个人经验影响。 | F13: 代码提交时，AI 节点自动检查是否关联了工作项、是否通过了 Code Review、是否包含必要的测试，不合规的提交自动拦截并通知开发者。 | G13: 前置发现问题｜统一审核标准｜降低合规风险 | H13: 汽车 | I13: 研发 | J13: 代码审查｜合规拦截 | K13: 流程节点 | L13: https://aka.doubaocdn.com/s/a3S9pUgsCz | O13: 是 | P13: 12 | Q13: 模拟待校准 | R13: 来源：用户筛选 CSV 序号 12；场景名称和描述已按流程节点口径整理。
... A32: S037 | B32: 审核报名资格 | C32: 质量检查与审核 | D32: 学科赛事报名时，AI 节点自动审核参赛资格：年级、学科、往届成绩等，不符合条件的自动驳回并说明原因。 | E32: 当前“审核报名资格”依赖人工读取材料、判断规则并执行后续操作，处理效率和结果一致性容易受个人经验影响。 | F32: 学科赛事报名时，AI 节点自动审核参赛资格：年级、学科、往届成绩等，不符合条件的自动驳回并说明原因。 | G32: 前置发现问题｜统一审核标准｜降低合规风险 | H32: 教育 | I32: 运营 | J32: 报名审核｜资格校验 | K32: 流程节点 | L32: https://aka.doubaocdn.com/s/hYfl2K2xZW | O32: 是 | P32: 31 | Q32: 模拟待校准 | R32: 来源：用户筛选 CSV 序号 111；场景名称和描述已按流程节点口径整理。
A33: S013 | B33: 外部工单接入项目闭环 | C33: 计划拆解与协同 | D33: 将客服或服务台工单自动创建为项目工作项，并同步状态与处理结果。 | E33: 外部工单与研发项目割裂，客服需要反复追问进度，状态同步依赖人工。 | F33: 通过插件接入外部工单，映射字段、自动建单并同步状态，完成后将结果回传原系统。 | G33: 打通内外流程｜减少状态搬运｜提升客户响应透明度 | H33: 互联网｜医疗｜零售 | I33: 运营｜研发｜项目经理 | J33: 系统集成｜工单管理｜状态同步 | K33: 图片 | O33: 是 | P33: 13 | Q33: 模拟待校准 | R33: 演示数据；产品能力、客户案例与量化结果上线前需逐项核实。
A34: S014 | B34: 代码提交关联研发任务 | C34: 计划拆解与协同 | D34: 自动将分支、提交和合并请求关联研发任务，并同步开发状态。 | E34: 代码与任务信息分散，项目进度依赖开发手动更新，追溯成本高。 | F34: 通过代码仓库插件识别任务编号，关联分支、提交和合并请求，并按规则更新任务状态。 | G34: 减少手动更新｜提升研发可追溯性｜让进度更实时 | H34: 互联网｜汽车｜消费电子 | I34: 研发｜项目经理｜测试 | J34: 研发协同｜代码关联｜自动流转 | K34: 图片 | O34: 是 | P34: 14 | Q34: 模拟待校准 | R34: 演示数据；产品能力、客户案例与量化结果上线前需逐项核实。
A35: S015 | B35: 管理驾驶舱快速搭建 | C35: 计划拆解与协同 | D35: 聚合项目进度、风险、资源和质量指标，为管理者提供一页式视图。 | E35: 管理数据散落在多个视图，汇报依赖截图和手工表格，缺少统一入口。 | F35: 按角色组合指标卡、趋势图和风险列表，连接项目数据源，形成可按组织筛选的驾驶舱。 | G35: 缩短管理取数路径｜统一经营视图｜支持持续复盘 | H35: 互联网｜制造｜汽车 | I35: 高管｜项目经理｜运营 | J35: 轻应用｜管理驾驶舱｜数据可视化 | K35: 图片 | O35: 是 | P35: 15 | Q35: 模拟待校准 | R35: 演示数据；产品能力、客户案例与量化结果上线前需逐项核实。
A36: S016 | B36: 会议联动项目汇报 | C36: 计划拆解与协同 | D36: 会前自动准备项目材料，会中展示关键数据，会后跟踪决议执行。 | E36: 例会材料准备耗时，会议与项目数据割裂，决议缺少持续跟踪。 | F36: 轻应用按会议议题聚合项目数据，会后将决议转为任务，并持续展示执行状态。 | G36: 减少会前准备｜连接会议与执行｜提升决议闭环率 | H36: 医疗｜制造｜互联网 | I36: 项目经理｜高管｜运营 | J36: 轻应用｜会议协同｜项目汇报 | K36: 图片 | O36: 是 | P36: 16 | Q36: 模拟待校准 | R36: 演示数据；产品能力、客户案例与量化结果上线前需逐项核实。
A37: S017 | B37: 软件研发流程快速启用 | D37: 用一套预置模板快速搭建需求、开发、测试和发布的研发流程。 | E37: 新团队从零设计流程成本高，字段、状态和视图容易缺失或不一致。 | F37: 复制研发模板后，根据团队规模调整工作项、流程、权限和度量视图，再导入存量项目。 | G37: 降低初始化成本｜复用成熟流程｜缩短上线周期 | H37: 互联网｜消费电子｜汽车 | I37: 项目经理｜研发｜测试 | J37: 模板｜研发管理｜流程搭建 | K37: 图片 | O37: 是 | P37: 17 | Q37: 模拟待校准 | R37: 演示数据；产品能力、客户案例与量化结果上线前需逐项核实。
A38: S018 | B38: 整车研发跨域协同 | D38: 围绕车型项目连接多域计划、评审、风险和交付，实现跨团队协同。 | E38: 整车研发周期长、参与域多，计划依赖关系和风险传递难以统一管理。 | F38: 基于解决方案搭建车型项目、跨域计划、关键评审与风险闭环，并连接组织级里程碑。 | G38: 统一跨域协作语言｜提升计划透明度｜强化风险闭环 | H38: 汽车｜制造 | I38: 项目经理｜研发｜高管 | J38: 解决方案｜整车研发｜跨域协同 | K38: 图片 | O38: 是 | P38: 18 | Q38: 模拟待校准 | R38: 演示数据；产品能力、客户案例与量化结果上线前需逐项核实。
A39: S038 | B39: 撰写产品 PRD | C39: 内容撰写与总结 | D39: 需求进入方案阶段后，AI 汇总背景、目标、范围、用户故事和验收标准，生成结构化 PRD 初稿。 | E39: 产品经理需要从访谈、会议纪要和零散需求中反复整理 PRD，文档结构与信息完整度依赖个人经验。 | F39: 需求进入方案阶段时，读取当前需求及关联的访谈记录、会议纪要和参考资料，按团队模板生成包含背景、目标、范围、用户故事、方案说明、验收标准和风险项的 PRD 初稿，并标记待确认信息。 | G39: 缩短文档起草时间｜统一 PRD 结构｜减少关键信息遗漏 | H39: 互联网｜消费电子｜零售 | I39: 产品经理 | J39: 需求文档｜结构化写作｜PRD | K39: 流程节点 | O39: 是 | P39: 32 | Q39: 模拟待校准 | R39: 用户指定新增场景；描述、提示词及映射为模拟内容，待产品能力确认。
A40: S039 | B40: 走查产品需求 | C40: 质量检查与审核 | D40: 需求提交评审前，AI 按 PM 走查清单检查目标、场景、范围、逻辑和验收标准，输出修改建议。 | E40: 需求走查依赖产品经理个人经验，范围遗漏、逻辑断点和验收标准不清常在正式评审时才暴露。 | F40: 需求提交评审前，读取 PRD、原型和关联背景，按团队 PM 走查清单检查目标是否明确、用户场景是否闭环、范围边界是否清晰、异常流程是否覆盖、验收标准是否可验证，并将问题和修改建议回写到工作项。 | G40: 前置发现需求问题｜统一走查标准｜提升正式评审效率 | H40: 互联网｜消费电子｜游戏 | I40: 产品经理｜项目经理 | J40: 需求走查｜逻辑检查｜评审准备 | K40: 流程节点 | O40: 是 | P40: 33 | Q40: 模拟待校准 | R40: 用户指定新增场景；描述、提示词及映射为模拟内容，待产品能力确认。
A41: S040 | B41: 总结项目成果 | C41: 内容撰写与总结 | D41: 项目或阶段结束后，AI 汇总目标达成、关键交付、风险处理和经验教训，生成项目总结初稿。 | E41: 项目总结依赖人工跨任务、文档和会议记录取数，容易只罗列过程，缺少目标对照和可复用经验。 | F41: 项目进入结项或阶段验收节点后，读取目标、里程碑、交付物、风险、变更和关键决策，生成包含目标达成情况、关键成果、问题与处理、经验教训和后续行动的项目总结，并保留信息来源。 | G41: 降低总结成本｜沉淀项目经验｜形成后续行动闭环 | H41: 互联网｜制造｜教育｜能源 | I41: 项目经理｜高管 | J41: 项目总结｜成果沉淀｜经验复用 | K41: 流程节点 | O41: 是 | P41: 34 | Q41: 模拟待校准 | R41: 用户指定新增场景；描述、提示词及映射为模拟内容，待产品能力确认。
A42: S041 | B42: 撰写产品手册 | C42: 内容撰写与总结 | D42: 版本验收后，AI 汇总功能说明、操作步骤和注意事项，生成面向用户的产品手册初稿。 | E42: 产品手册需要人工汇总需求、原型和操作说明，更新经常滞后于版本，用户难以及时理解新功能。 | F42: 版本进入验收或发布节点后，读取已交付需求、功能说明、操作步骤、权限限制和常见问题，按产品手册目录生成面向用户的云文档，并标记缺失截图和待确认内容。 | G42: 缩短手册编写时间｜保持文档与版本一致｜降低用户学习成本 | H42: 互联网｜消费电子｜教育 | I42: 产品经理｜运营 | J42: 产品手册｜用户文档｜知识沉淀 | K42: 流程节点 | O42: 是 | P42: 35 | Q42: 模拟待校准 | R42: 用户指定新增场景；描述、提示词及映射为模拟内容，待产品能力确认。

Sheet 产品表
A1: 产品ID | B1: 产品名称 | C1: 产品类型 | D1: 产品子类型 | E1: 卡片短描述 | F1: 详情介绍 | G1: 核心能力 | H1: 适用行业 | I1: 适用角色 | J1: 图标 | K1: 封面图片 | L1: 提供方 | M1: 最近更新时间 | N1: 直接使用链接 | O1: 配置说明链接 | P1: 产品文档链接 | Q1: 来源URL | R1: 目录是否展示 | S1: 目录排序 | T1: 内容状态 | U1: 真实性备注
A2: A001 | B2: 自定义指令 | C2: AI应用 | D2: AI字段 | E2: 灵活编写提示词，定制个性化 AI 输出。 | F2: 自定义指令用于灵活编写提示词，定制个性化 AI 输出，可作为相关最佳实践的实现资产。 | G2: 自定义提示词｜字段输出｜个性化配置 | H2: 互联网｜汽车｜制造｜金融 | I2: 产品经理｜项目经理｜研发｜测试 | L2: 飞书项目（模拟） | Q2: https://project.feishu.cn/home/developers | R2: 是 | S2: 1 | T2: 草稿 | U2: 名称与核心描述来自飞书项目开放平台官网；图片、详情和目标链接仍需补充或复核。
A3: A002 | B3: 智能打分 | C3: AI应用 | D3: AI字段 | E3: 按标准智能量化评分，提升评估效率。 | F3: 智能打分用于按标准智能量化评分，提升评估效率，可作为相关最佳实践的实现资产。 | G3: 评分标准｜量化评估｜结果写入 | H3: 互联网｜汽车｜制造｜金融 | I3: 产品经理｜项目经理｜研发｜测试 | L3: 飞书项目（模拟） | Q3: https://project.feishu.cn/home/developers | R3: 是 | S3: 2 | T3: 草稿 | U3: 名称与核心描述来自飞书项目开放平台官网；图片、详情和目标链接仍需补充或复核。
A4: A003 | B4: 分类打标 | C4: AI应用 | D4: AI字段 | E4: 智能匹配分类标签，提升内容检索效率。 | F4: 分类打标用于智能匹配分类标签，提升内容检索效率，可作为相关最佳实践的实现资产。 | G4: 智能分类｜标签匹配｜字段写入 | H4: 互联网｜汽车｜制造｜金融 | I4: 产品经理｜项目经理｜研发｜测试 | L4: 飞书项目（模拟） | Q4: https://project.feishu.cn/home/developers | R4: 是 | S4: 3 | T4: 草稿 | U4: 名称与核心描述来自飞书项目开放平台官网；图片、详情和目标链接仍需补充或复核。
A5: A004 | B5: 关键内容提取 | C5: AI应用 | D5: AI字段 | E5: 精准提取关键信息，提升文本处理效率。 | F5: 关键内容提取用于精准提取关键信息，提升文本处理效率，可作为相关最佳实践的实现资产。 | G5: 信息提取｜结构化输出｜字段写入 | H5: 互联网｜汽车｜制造｜金融 | I5: 产品经理｜项目经理｜研发｜测试 | L5: 飞书项目（模拟） | Q5: https://project.feishu.cn/home/developers | R5: 是 | S5: 4 | T5: 草稿 | U5: 名称与核心描述来自飞书项目开放平台官网；图片、详情和目标链接仍需补充或复核。
A6: A005 | B6: 内容总结 | C6: AI应用 | D6: AI字段 | E6: 智能提炼长文本，生成清晰结构化总结。 | F6: 内容总结用于智能提炼长文本，生成清晰结构化总结，可作为相关最佳实践的实现资产。 | G6: 长文总结｜结构化摘要｜字段生成 | H6: 互联网｜汽车｜制造｜金融 | I6: 产品经理｜项目经理｜研发｜测试 | L6: 飞书项目（模拟） | Q6: https://project.feishu.cn/home/developers | R6: 是 | S6: 5 | T6: 草稿 | U6: 名称与核心描述来自飞书项目开放平台官网；图片、详情和目标链接仍需补充或复核。
A7: A006 | B7: 智能翻译 | C7: AI应用 | D7: AI字段 | E7: 精准翻译多语言内容，保留原文语义结构。 | F7: 智能翻译用于精准翻译多语言内容，保留原文语义结构，可作为相关最佳实践的实现资产。 | G7: 多语言翻译｜语义保留｜字段生成 | H7: 互联网｜汽车｜制造｜金融 | I7: 产品经理｜项目经理｜研发｜测试 | L7: 飞书项目（模拟） | Q7: https://project.feishu.cn/home/developers | R7: 是 | S7: 6 | T7: 草稿 | U7: 名称与核心描述来自飞书项目开放平台官网；图片、详情和目标链接仍需补充或复核。
A8: A007 | B8: AI 智能洞察 | C8: AI应用 | D8: AI节点 | E8: 一键分析项目数据，生成洞察报告。 | F8: AI 智能洞察用于一键分析项目数据，生成洞察报告，可作为相关最佳实践的实现资产。 | G8: 项目分析｜洞察报告｜风险识别 | H8: 互联网｜汽车｜制造｜金融 | I8: 产品经理｜项目经理｜研发｜测试 | L8: 飞书项目（模拟） | Q8: https://project.feishu.cn/home/developers | R8: 是 | S8: 7 | T8: 草稿 | U8: 名称与核心描述来自飞书项目开放平台官网；图片、详情和目标链接仍需补充或复核。
A9: A008 | B9: AI 智能填单 | C9: AI应用 | D9: AI节点 | E9: 智能提取文档信息，一键回填项目字段。 | F9: AI 智能填单用于智能提取文档信息，一键回填项目字段，可作为相关最佳实践的实现资产。 | G9: 文档提取｜字段映射｜一键回填 | H9: 互联网｜汽车｜制造｜金融 | I9: 产品经理｜项目经理｜研发｜测试 | L9: 飞书项目（模拟） | Q9: https://project.feishu.cn/home/developers | R9: 是 | S9: 8 | T9: 草稿 | U9: 名称与核心描述来自飞书项目开放平台官网；图片、详情和目标链接仍需补充或复核。
A10: A009 | B10: 智能测试用例生成 | C10: AI应用 | D10: AI节点 | E10: 智能生成测试用例，提升覆盖率与交付效率。 | F10: 智能测试用例生成用于智能生成测试用例，提升覆盖率与交付效率，可作为相关最佳实践的实现资产。 | G10: 用例生成｜覆盖提升｜质量协同 | H10: 互联网｜汽车｜制造｜金融 | I10: 产品经理｜项目经理｜研发｜测试 | L10: 飞书项目（模拟） | Q10: https://project.feishu.cn/home/developers | R10: 是 | S10: 9 | T10: 草稿 | U10: 名称与核心描述来自飞书项目开放平台官网；图片、详情和目标链接仍需补充或复核。
A11: A010 | B11: 智能体连接器 | C11: AI应用 | D11: AI节点 | E11: 连接 Agent 与项目，自动流转任务。 | F11: 智能体连接器用于连接 Agent 与项目，自动流转任务，可作为相关最佳实践的实现资产。 | G11: Agent 连接｜任务流转｜项目协同 | H11: 互联网｜汽车｜制造｜金融 | I11: 产品经理｜项目经理｜研发｜测试 | L11: 飞书项目（模拟） | Q11: https://project.feishu.cn/home/developers | R11: 是 | S11: 10 | T11: 草稿 | U11: 名称与核心描述来自飞书项目开放平台官网；图片、详情和目标链接仍需补充或复核。
A12: A011 | B12: AI 生成云文档 | C12: AI应用 | D12: AI节点 | E12: 智能生成规范需求文档，提升 PRD 产出效率。 | F12: AI 生成云文档用于智能生成规范需求文档，提升 PRD 产出效率，可作为相关最佳实践的实现资产。 | G12: 需求文档｜规范生成｜云文档 | H12: 互联网｜汽车｜制造｜金融 | I12: 产品经理｜项目经理｜研发｜测试 | L12: 飞书项目（模拟） | Q12: https://project.feishu.cn/home/developers | R12: 是 | S12: 11 | T12: 草稿 | U12: 名称与核心描述来自飞书项目开放平台官网；图片、详情和目标链接仍需补充或复核。
A13: A012 | B13: 智能会议分析 | C13: AI应用 | D13: AI节点 | E13: 智能分析会议内容，一键生成项目子任务。 | F13: 智能会议分析用于智能分析会议内容，一键生成项目子任务，可作为相关最佳实践的实现资产。 | G13: 会议分析｜子任务生成｜行动项提取 | H13: 互联网｜汽车｜制造｜金融 | I13: 产品经理｜项目经理｜研发｜测试 | L13: 飞书项目（模拟） | Q13: https://project.feishu.cn/home/developers | R13: 是 | S13: 12 | T13: 草稿 | U13: 名称与核心描述来自飞书项目开放平台官网；图片、详情和目标链接仍需补充或复核。
... A20: P007 | B20: GitLab 研发连接器 | C20: 插件 | D20: 代码集成 | E20: 关联 Branch、Commit、MR 与工作项，并通过 Merge 事件自动流转。 | F20: GitLab 研发连接器用于关联 Branch、Commit、MR 与工作项，并通过 Merge 事件自动流转，可作为相关最佳实践的实现资产。 | G20: 代码关联｜状态同步｜研发追溯 | H20: 互联网｜汽车｜制造｜金融 | I20: 项目经理｜研发｜测试｜运营 | L20: 飞书项目（模拟） | Q20: https://project.feishu.cn/home/developers | R20: 是 | S20: 7 | T20: 草稿 | U20: 名称与核心描述来自飞书项目开放平台官网；图片、详情和目标链接仍需补充或复核。
A21: P008 | B21: 多维表格同步 | C21: 插件 | D21: 数据同步 | E21: 在项目工作项与多维表格间同步结构化数据。 | F21: 多维表格同步用于在项目工作项与多维表格间同步结构化数据，可作为相关最佳实践的实现资产。 | G21: 双向同步｜字段映射｜冲突处理 | H21: 互联网｜汽车｜制造｜金融 | I21: 项目经理｜研发｜测试｜运营 | L21: 飞书项目（模拟） | R21: 是 | S21: 8 | T21: 模拟待校准 | U21: 演示命名与描述；上线前请替换为真实产品名称、截图、链接和官方说明。
A22: P009 | B22: 飞书消息转任务 | C22: 插件 | D22: 消息集成 | E22: 将会话消息快速创建为项目任务并保留来源。 | F22: 飞书消息转任务用于将会话消息快速创建为项目任务并保留来源，可作为相关最佳实践的实现资产。 | G22: 消息建单｜上下文保留｜任务关联 | H22: 互联网｜汽车｜制造｜金融 | I22: 项目经理｜研发｜测试｜运营 | L22: 飞书项目（模拟） | R22: 是 | S22: 9 | T22: 模拟待校准 | U22: 演示命名与描述；上线前请替换为真实产品名称、截图、链接和官方说明。
A23: P010 | B23: 测试管理增强 | C23: 插件 | D23: 质量管理 | E23: 管理测试计划、用例、执行与缺陷关联。 | F23: 测试管理增强用于管理测试计划、用例、执行与缺陷关联，可作为相关最佳实践的实现资产。 | G23: 用例管理｜执行跟踪｜覆盖分析 | H23: 互联网｜汽车｜制造｜金融 | I23: 项目经理｜研发｜测试｜运营 | L23: 飞书项目（模拟） | R23: 是 | S23: 10 | T23: 模拟待校准 | U23: 演示命名与描述；上线前请替换为真实产品名称、截图、链接和官方说明。
A24: P011 | B24: 审批流程增强 | C24: 插件 | D24: 流程增强 | E24: 为复杂业务提供多级审批与条件流转能力。 | F24: 审批流程增强用于为复杂业务提供多级审批与条件流转能力，可作为相关最佳实践的实现资产。 | G24: 条件审批｜多级流转｜审计记录 | H24: 互联网｜汽车｜制造｜金融 | I24: 项目经理｜研发｜测试｜运营 | L24: 飞书项目（模拟） | R24: 是 | S24: 11 | T24: 模拟待校准 | U24: 演示命名与描述；上线前请替换为真实产品名称、截图、链接和官方说明。
A25: P012 | B25: 开放 API 调试台 | C25: 插件 | D25: 开发工具 | E25: 辅助调试项目开放接口与事件订阅。 | F25: 开放 API 调试台用于辅助调试项目开放接口与事件订阅，可作为相关最佳实践的实现资产。 | G25: 接口调试｜事件验证｜日志查看 | H25: 互联网｜汽车｜制造｜金融 | I25: 项目经理｜研发｜测试｜运营 | L25: 飞书项目（模拟） | R25: 是 | S25: 12 | T25: 模拟待校准 | U25: 演示命名与描述；上线前请替换为真实产品名称、截图、链接和官方说明。
A26: T001 | B26: DSTE战略到执行 | C26: 模板 | D26: 战略管理 | E26: 打通战略制定、目标分解、项目推进与经营复盘。 | F26: DSTE战略到执行用于打通战略制定、目标分解、项目推进与经营复盘，可作为相关最佳实践的实现资产。 | G26: 战略地图｜指标看板｜执行闭环 | H26: 互联网｜汽车｜制造｜零售 | I26: 项目经理｜产品经理｜运营｜高管 | L26: 飞书项目（模拟） | Q26: https://project.feishu.cn/home/developers | R26: 是 | S26: 1 | T26: 草稿 | U26: 名称与核心描述来自飞书项目开放平台官网；图片、详情和目标链接仍需补充或复核。
A27: T002 | B27: 软件研发管理 | C27: 模板 | D27: 研发管理 | E27: 覆盖需求、任务、缺陷、迭代、测试、代码与发布全流程。 | F27: 软件研发管理用于覆盖需求、任务、缺陷、迭代、测试、代码与发布全流程，可作为相关最佳实践的实现资产。 | G27: 需求管理｜迭代管理｜质量追踪 | H27: 互联网｜汽车｜制造｜零售 | I27: 项目经理｜产品经理｜运营｜高管 | L27: 飞书项目（模拟） | Q27: https://project.feishu.cn/home/developers | R27: 是 | S27: 2 | T27: 草稿 | U27: 名称与核心描述来自飞书项目开放平台官网；图片、详情和目标链接仍需补充或复核。
A28: T003 | B28: 内容制作全流程 | C28: 模板 | D28: 内容运营 | E28: 覆盖创意收集、选题、素材、创作、分发与复盘。 | F28: 内容制作全流程用于覆盖创意收集、选题、素材、创作、分发与复盘，可作为相关最佳实践的实现资产。 | G28: 内容策划｜素材沉淀｜分发复盘 | H28: 互联网｜汽车｜制造｜零售 | I28: 项目经理｜产品经理｜运营｜高管 | L28: 飞书项目（模拟） | Q28: https://project.feishu.cn/home/developers | R28: 是 | S28: 3 | T28: 草稿 | U28: 名称与核心描述来自飞书项目开放平台官网；图片、详情和目标链接仍需补充或复核。
A29: T004 | B29: 软件交付项目模板 | C29: 模板 | D29: 项目交付 | E29: 管理交付计划、风险、验收与上线。 | F29: 软件交付项目模板用于管理交付计划、风险、验收与上线，可作为相关最佳实践的实现资产。 | G29: 计划管理｜风险跟踪｜交付验收 | H29: 互联网｜汽车｜制造｜零售 | I29: 项目经理｜产品经理｜运营｜高管 | L29: 飞书项目（模拟） | R29: 是 | S29: 4 | T29: 模拟待校准 | U29: 演示命名与描述；上线前请替换为真实产品名称、截图、链接和官方说明。
A30: T005 | B30: 版本发布管理模板 | C30: 模板 | D30: 发布管理 | E30: 协调多端版本、变更、检查与发布。 | F30: 版本发布管理模板用于协调多端版本、变更、检查与发布，可作为相关最佳实践的实现资产。 | G30: 版本计划｜发布门禁｜变更记录 | H30: 互联网｜汽车｜制造｜零售 | I30: 项目经理｜产品经理｜运营｜高管 | L30: 飞书项目（模拟） | R30: 是 | S30: 5 | T30: 模拟待校准 | U30: 演示命名与描述；上线前请替换为真实产品名称、截图、链接和官方说明。
A31: T006 | B31: 测试全流程模板 | C31: 模板 | D31: 质量管理 | E31: 组织测试计划、用例执行和缺陷闭环。 | F31: 测试全流程模板用于组织测试计划、用例执行和缺陷闭环，可作为相关最佳实践的实现资产。 | G31: 测试计划｜用例执行｜缺陷管理 | H31: 互联网｜汽车｜制造｜零售 | I31: 项目经理｜产品经理｜运营｜高管 | L31: 飞书项目（模拟） | R31: 是 | S31: 6 | T31: 模拟待校准 | U31: 演示命名与描述；上线前请替换为真实产品名称、截图、链接和官方说明。
A32: T007 | B32: 市场活动项目模板 | C32: 模板 | D32: 营销运营 | E32: 管理活动策划、素材、执行与复盘。 | F32: 市场活动项目模板用于管理活动策划、素材、执行与复盘，可作为相关最佳实践的实现资产。 | G32: 活动计划｜素材协作｜效果复盘 | H32: 互联网｜汽车｜制造｜零售 | I32: 项目经理｜产品经理｜运营｜高管 | L32: 飞书项目（模拟） | R32: 是 | S32: 7 | T32: 模拟待校准 | U32: 演示命名与描述；上线前请替换为真实产品名称、截图、链接和官方说明。
A33: T008 | B33: 内容生产流程模板 | C33: 模板 | D33: 内容运营 | E33: 管理选题、脚本、制作、发布和数据复盘。 | F33: 内容生产流程模板用于管理选题、脚本、制作、发布和数据复盘，可作为相关最佳实践的实现资产。 | G33: 内容策划｜制作协同｜发布复盘 | H33: 互联网｜汽车｜制造｜零售 | I33: 项目经理｜产品经理｜运营｜高管 | L33: 飞书项目（模拟） | R33: 是 | S33: 8 | T33: 模拟待校准 | U33: 演示命名与描述；上线前请替换为真实产品名称、截图、链接和官方说明。
A34: T009 | B34: 门店开业项目模板 | C34: 模板 | D34: 零售运营 | E34: 管理选址、筹备、验收和开业节点。 | F34: 门店开业项目模板用于管理选址、筹备、验收和开业节点，可作为相关最佳实践的实现资产。 | G34: 筹备计划｜节点验收｜问题闭环 | H34: 互联网｜汽车｜制造｜零售 | I34: 项目经理｜产品经理｜运营｜高管 | L34: 飞书项目（模拟） | R34: 是 | S34: 9 | T34: 模拟待校准 | U34: 演示命名与描述；上线前请替换为真实产品名称、截图、链接和官方说明。
A35: T010 | B35: 合同履约管理模板 | C35: 模板 | D35: 合同管理 | E35: 连接合同条款、交付计划与验收回款。 | F35: 合同履约管理模板用于连接合同条款、交付计划与验收回款，可作为相关最佳实践的实现资产。 | G35: 条款记录｜履约计划｜验收回款 | H35: 互联网｜汽车｜制造｜零售 | I35: 项目经理｜产品经理｜运营｜高管 | L35: 飞书项目（模拟） | R35: 是 | S35: 10 | T35: 模拟待校准 | U35: 演示命名与描述；上线前请替换为真实产品名称、截图、链接和官方说明。
A36: T011 | B36: 战略执行管理模板 | C36: 模板 | D36: 战略管理 | E36: 连接目标、项目集、项目与执行任务。 | F36: 战略执行管理模板用于连接目标、项目集、项目与执行任务，可作为相关最佳实践的实现资产。 | G36: 目标分解｜项目组合｜执行跟踪 | H36: 互联网｜汽车｜制造｜零售 | I36: 项目经理｜产品经理｜运营｜高管 | L36: 飞书项目（模拟） | R36: 是 | S36: 11 | T36: 模拟待校准 | U36: 演示命名与描述；上线前请替换为真实产品名称、截图、链接和官方说明。
A37: T012 | B37: 供应商项目模板 | C37: 模板 | D37: 供应链管理 | E37: 管理供应商准入、交付、质量与改进。 | F37: 供应商项目模板用于管理供应商准入、交付、质量与改进，可作为相关最佳实践的实现资产。 | G37: 供应商准入｜交付跟踪｜质量改进 | H37: 互联网｜汽车｜制造｜零售 | I37: 项目经理｜产品经理｜运营｜高管 | L37: 飞书项目（模拟） | R37: 是 | S37: 12 | T37: 模拟待校准 | U37: 演示命名与描述；上线前请替换为真实产品名称、截图、链接和官方说明。
A38: O001 | B38: 规模化敏捷 | C38: 解决方案 | D38: 敏捷研发 | E38: 基于 SAFe 框架支持 PI Planning 全流程管理。 | F38: 规模化敏捷用于基于 SAFe 框架支持 PI Planning 全流程管理，可作为相关最佳实践的实现资产。 | G38: ART 看板｜团队看板｜依赖报告 | H38: 汽车｜制造｜金融｜互联网 | I38: 高管｜项目经理｜研发 | L38: 飞书项目（模拟） | Q38: https://project.feishu.cn/home/developers | R38: 是 | S38: 1 | T38: 草稿 | U38: 名称与核心描述来自飞书项目开放平台官网；图片、详情和目标链接仍需补充或复核。
A39: O002 | B39: 翼云销LTC解决方案 | C39: 解决方案 | D39: LTC管理 | E39: 以 AI 为核心打通线索、商机、签约、交付到回款全流程。 | F39: 翼云销LTC解决方案用于以 AI 为核心打通线索、商机、签约、交付到回款全流程，可作为相关最佳实践的实现资产。 | G39: 客户录入｜方案推荐｜风险预警 | H39: 汽车｜制造｜金融｜互联网 | I39: 高管｜项目经理｜研发 | L39: 飞书项目（模拟） | Q39: https://project.feishu.cn/home/developers | R39: 是 | S39: 2 | T39: 草稿 | U39: 名称与核心描述来自飞书项目开放平台官网；图片、详情和目标链接仍需补充或复核。
A40: O003 | B40: Zadig DevOps 一体化解决方案 | C40: 解决方案 | D40: DevOps | E40: 打通需求、开发、自测、测试到生产发布全流程。 | F40: Zadig DevOps 一体化解决方案用于打通需求、开发、自测、测试到生产发布全流程，可作为相关最佳实践的实现资产。 | G40: 构建部署｜测试审批｜状态同步 | H40: 汽车｜制造｜金融｜互联网 | I40: 高管｜项目经理｜研发 | L40: 飞书项目（模拟） | Q40: https://project.feishu.cn/home/developers | R40: 是 | S40: 3 | T40: 草稿 | U40: 名称与核心描述来自飞书项目开放平台官网；图片、详情和目标链接仍需补充或复核。
A41: O004 | B41: ASPICE 汽车软件研发方案 | C41: 解决方案 | D41: 汽车研发 | E41: 连接项目、知识库与云文档，支撑汽车软件 V 模型和认证。 | F41: ASPICE 汽车软件研发方案用于连接项目、知识库与云文档，支撑汽车软件 V 模型和认证，可作为相关最佳实践的实现资产。 | G41: 需求条目化｜版本管理｜V 模型 | H41: 汽车｜制造｜金融｜互联网 | I41: 高管｜项目经理｜研发 | L41: 飞书项目（模拟） | Q41: https://project.feishu.cn/home/developers | R41: 是 | S41: 4 | T41: 草稿 | U41: 名称与核心描述来自飞书项目开放平台官网；图片、详情和目标链接仍需补充或复核。
A42: O005 | B42: 制造业项目协同解决方案 | C42: 解决方案 | D42: 制造行业 | E42: 管理研发、供应链、质量和交付协同。 | F42: 制造业项目协同解决方案用于管理研发、供应链、质量和交付协同，可作为相关最佳实践的实现资产。 | G42: 研发协同｜供应链风险｜质量追踪 | H42: 汽车｜制造｜金融｜互联网 | I42: 高管｜项目经理｜研发 | L42: 飞书项目（模拟） | R42: 是 | S42: 5 | T42: 模拟待校准 | U42: 演示命名与描述；上线前请替换为真实产品名称、截图、链接和官方说明。
A43: O006 | B43: 金融科技项目治理方案 | C43: 解决方案 | D43: 金融行业 | E43: 加强需求、合规、研发和发布治理。 | F43: 金融科技项目治理方案用于加强需求、合规、研发和发布治理，可作为相关最佳实践的实现资产。 | G43: 需求治理｜合规检查｜发布审计 | H43: 汽车｜制造｜金融｜互联网 | I43: 高管｜项目经理｜研发 | L43: 飞书项目（模拟） | R43: 是 | S43: 6 | T43: 模拟待校准 | U43: 演示命名与描述；上线前请替换为真实产品名称、截图、链接和官方说明。
A44: L001 | B44: 项目管理驾驶舱 | C44: 轻应用 | D44: 管理驾驶舱 | E44: 聚合关键项目指标与风险。 | F44: 项目管理驾驶舱用于聚合关键项目指标与风险，可作为相关最佳实践的实现资产。 | G44: 指标卡｜趋势图｜风险列表 | H44: 互联网｜汽车｜制造｜医疗 | I44: 高管｜项目经理｜运营 | L44: 飞书项目（模拟） | R44: 否 | S44: 1 | T44: 模拟待校准 | U44: 演示命名与描述；上线前请替换为真实产品名称、截图、链接和官方说明。
A45: L002 | B45: 会议联动汇报台 | C45: 轻应用 | D45: 会议协同 | E45: 连接议题、项目数据和会后决议。 | F45: 会议联动汇报台用于连接议题、项目数据和会后决议，可作为相关最佳实践的实现资产。 | G45: 会前材料｜会中展示｜会后跟踪 | H45: 互联网｜汽车｜制造｜医疗 | I45: 高管｜项目经理｜运营 | L45: 飞书项目（模拟） | R45: 否 | S45: 2 | T45: 模拟待校准 | U45: 演示命名与描述；上线前请替换为真实产品名称、截图、链接和官方说明。
A46: L003 | B46: 个人项目工作台 | C46: 轻应用 | D46: 个人效率 | E46: 聚合个人任务、风险和待处理事项。 | F46: 个人项目工作台用于聚合个人任务、风险和待处理事项，可作为相关最佳实践的实现资产。 | G46: 个人任务｜优先级｜快捷操作 | H46: 互联网｜汽车｜制造｜医疗 | I46: 高管｜项目经理｜运营 | L46: 飞书项目（模拟） | R46: 否 | S46: 3 | T46: 模拟待校准 | U46: 演示命名与描述；上线前请替换为真实产品名称、截图、链接和官方说明。
...

Sheet 场景产品关系表
A1: 关系ID | B1: 场景ID | C1: 产品ID | D1: 是否主要实现 | E1: 使用方法概述 | F1: 操作步骤 | G1: 交付类型 | H1: 参考提示词 | I1: PRD正文 | J1: PRD链接 | K1: 搭建说明链接 | L1: 目标链接 | M1: 按钮文案 | N1: 配置注意事项 | O1: 预期产出 | P1: 内容状态
A2: R021 | B2: S001 | C2: A008 | D2: 是 | E2: 在对应流程节点中配置AI 智能填单，自动完成补全客户信息。 | F2: 选择触发节点｜配置输入材料｜定义输出字段｜用样例验证 | G2: 参考提示词 | H2: 你是项目流程中的“补全客户信息”助手。请结合当前工作项、关联字段和附件完成以下任务：1. 按场景规则处理输入信息；2. 输出可直接写回项目的结构化结果；3. 标注判断依据和待人工确认项；4. 不补充材料中不存在的事实。场景要求：需求评审后，AI 节点自动从会议纪要、邮件中提取关键信息，一键回填到飞书项目字段，无需手动逐条录入。 | M2: 复制参考提示词 | N2: 示例内容；上线前需校验字段、权限、触发条件和人工复核机制。 | O2: 补全客户信息 | P2: 模拟待校准
A3: R022 | B3: S002 | C3: A012 | D3: 是 | E3: 在对应流程节点中配置AI 智能会议分析，自动完成拆解会议任务。 | F3: 选择触发节点｜配置输入材料｜定义输出字段｜用样例验证 | G3: 参考提示词 | H3: 你是项目流程中的“拆解会议任务”助手。请结合当前工作项、关联字段和附件完成以下任务：1. 按场景规则处理输入信息；2. 输出可直接写回项目的结构化结果；3. 标注判断依据和待人工确认项；4. 不补充材料中不存在的事实。场景要求：需求评审会结束后，AI 节点自动提取所有待办项和决策要点，一键生成飞书项目子任务并关联到对应工作项，从讨论到执行无缝衔接。 | M3: 复制参考提示词 | N3: 示例内容；上线前需校验字段、权限、触发条件和人工复核机制。 | O3: 拆解会议任务 | P3: 模拟待校准
A4: R023 | B4: S003 | C4: A013 | D4: 是 | E4: 在对应流程节点中配置AI 助手，自动完成创建外部工单。 | F4: 选择触发节点｜配置输入材料｜定义输出字段｜用样例验证 | G4: 参考提示词 | H4: 你是项目流程中的“创建外部工单”助手。请结合当前工作项、关联字段和附件完成以下任务：1. 按场景规则处理输入信息；2. 输出可直接写回项目的结构化结果；3. 标注判断依据和待人工确认项；4. 不补充材料中不存在的事实。场景要求：客服系统、邮件、飞书群中的用户反馈，AI 节点自动识别并创建为标准工单，无需人工逐个录入，大幅提升工单处理效率。 | M4: 复制参考提示词 | N4: 示例内容；上线前需校验字段、权限、触发条件和人工复核机制。 | O4: 创建外部工单 | P4: 模拟待校准
A5: R024 | B5: S004 | C5: A013 | D5: 是 | E5: 在对应流程节点中配置AI 助手，自动完成创建邮件任务。 | F5: 选择触发节点｜配置输入材料｜定义输出字段｜用样例验证 | G5: 参考提示词 | H5: 你是项目流程中的“创建邮件任务”助手。请结合当前工作项、关联字段和附件完成以下任务：1. 按场景规则处理输入信息；2. 输出可直接写回项目的结构化结果；3. 标注判断依据和待人工确认项；4. 不补充材料中不存在的事实。场景要求：客户或合作方通过邮件提交的需求，AI 节点自动解析邮件内容并生成飞书项目工作项，避免遗漏重要邮件中的待办事项。 | M5: 复制参考提示词 | N5: 示例内容；上线前需校验字段、权限、触发条件和人工复核机制。 | O5: 创建邮件任务 | P5: 模拟待校准
A6: R025 | B6: S005 | C6: A013 | D6: 是 | E6: 在对应流程节点中配置AI 助手，自动完成提取合同条款。 | F6: 选择触发节点｜配置输入材料｜定义输出字段｜用样例验证 | G6: 参考提示词 | H6: 你是项目流程中的“提取合同条款”助手。请结合当前工作项、关联字段和附件完成以下任务：1. 按场景规则处理输入信息；2. 输出可直接写回项目的结构化结果；3. 标注判断依据和待人工确认项；4. 不补充材料中不存在的事实。场景要求：上传合同文件后，AI 节点自动提取金额、期限、违约责任等关键条款，结构化录入到工作项字段，减少人工核对时间。 | M6: 复制参考提示词 | N6: 示例内容；上线前需校验字段、权限、触发条件和人工复核机制。 | O6: 提取合同条款 | P6: 模拟待校准
A7: R026 | B7: S006 | C7: A013 | D7: 是 | E7: 在对应流程节点中配置AI 助手，自动完成分类客户反馈。 | F7: 选择触发节点｜配置输入材料｜定义输出字段｜用样例验证 | G7: 参考提示词 | H7: 你是项目流程中的“分类客户反馈”助手。请结合当前工作项、关联字段和附件完成以下任务：1. 按场景规则处理输入信息；2. 输出可直接写回项目的结构化结果；3. 标注判断依据和待人工确认项；4. 不补充材料中不存在的事实。场景要求：客服收到用户反馈后，AI 节点自动判断是 Bug、需求还是咨询，秒级路由到对应模块，减少人工分类和转派时间。 | M7: 复制参考提示词 | N7: 示例内容；上线前需校验字段、权限、触发条件和人工复核机制。 | O7: 分类客户反馈 | P7: 模拟待校准
A8: R027 | B8: S007 | C8: A014 | D8: 是 | E8: 在对应流程节点中配置AI 智能分配，自动完成分派研发需求。 | F8: 选择触发节点｜配置输入材料｜定义输出字段｜用样例验证 | G8: 参考提示词 | H8: 你是项目流程中的“分派研发需求”助手。请结合当前工作项、关联字段和附件完成以下任务：1. 按场景规则处理输入信息；2. 输出可直接写回项目的结构化结果；3. 标注判断依据和待人工确认项；4. 不补充材料中不存在的事实。场景要求：新需求进入开发阶段时，AI 节点自动匹配最合适的开发人员，兼顾技能匹配度和当前工作负载，避免忙闲不均，减少人工派单时间。 | M8: 复制参考提示词 | N8: 示例内容；上线前需校验字段、权限、触发条件和人工复核机制。 | O8: 分派研发需求 | P8: 模拟待校准
A9: R028 | B9: S008 | C9: A015 | D9: 是 | E9: 在对应流程节点中配置AI 缺陷分级，自动完成评定缺陷等级。 | F9: 选择触发节点｜配置输入材料｜定义输出字段｜用样例验证 | G9: 参考提示词 | H9: 你是项目流程中的“评定缺陷等级”助手。请结合当前工作项、关联字段和附件完成以下任务：1. 按场景规则处理输入信息；2. 输出可直接写回项目的结构化结果；3. 标注判断依据和待人工确认项；4. 不补充材料中不存在的事实。场景要求：测试提交 Bug 后，AI 根据严重程度、影响范围和修复成本自动分级，并推荐对应的处理人。 | M9: 复制参考提示词 | N9: 示例内容；上线前需校验字段、权限、触发条件和人工复核机制。 | O9: 评定缺陷等级 | P9: 模拟待校准
A10: R029 | B10: S009 | C10: A016 | D10: 是 | E10: 在对应流程节点中配置AI 工单分流，自动完成分流客服工单。 | F10: 选择触发节点｜配置输入材料｜定义输出字段｜用样例验证 | G10: 参考提示词 | H10: 你是项目流程中的“分流客服工单”助手。请结合当前工作项、关联字段和附件完成以下任务：1. 按场景规则处理输入信息；2. 输出可直接写回项目的结构化结果；3. 标注判断依据和待人工确认项；4. 不补充材料中不存在的事实。场景要求：电商平台的客服工单根据产品线、问题类型和用户等级自动分流到对应处理组，SLA 超时自动升级。 | M10: 复制参考提示词 | N10: 示例内容；上线前需校验字段、权限、触发条件和人工复核机制。 | O10: 分流客服工单 | P10: 模拟待校准
A11: R030 | B11: S010 | C11: A017 | D11: 是 | E11: 在对应流程节点中配置AI 质量检查，自动完成检查交付质量。 | F11: 选择触发节点｜配置输入材料｜定义输出字段｜用样例验证 | G11: 参考提示词 | H11: 你是项目流程中的“检查交付质量”助手。请结合当前工作项、关联字段和附件完成以下任务：1. 按场景规则处理输入信息；2. 输出可直接写回项目的结构化结果；3. 标注判断依据和待人工确认项；4. 不补充材料中不存在的事实。场景要求：提测节点中，AI 节点自动检查代码是否关联了需求、测试用例是否覆盖了验收标准，不符合的自动驳回并给出原因。 | M11: 复制参考提示词 | N11: 示例内容；上线前需校验字段、权限、触发条件和人工复核机制。 | O11: 检查交付质量 | P11: 模拟待校准
A12: R031 | B12: S011 | C12: A018 | D12: 是 | E12: 在对应流程节点中配置AI 合规审计，自动完成检查需求合规。 | F12: 选择触发节点｜配置输入材料｜定义输出字段｜用样例验证 | G12: 参考提示词 | H12: 你是项目流程中的“检查需求合规”助手。请结合当前工作项、关联字段和附件完成以下任务：1. 按场景规则处理输入信息；2. 输出可直接写回项目的结构化结果；3. 标注判断依据和待人工确认项；4. 不补充材料中不存在的事实。场景要求：需求提交审批前，AI 节点自动检查是否满足了合规要求：是否完成了风险评估、是否获得了法务审批、是否标注了数据安全等级。 | M12: 复制参考提示词 | N12: 示例内容；上线前需校验字段、权限、触发条件和人工复核机制。 | O12: 检查需求合规 | P12: 模拟待校准
A13: R032 | B13: S012 | C13: A019 | D13: 是 | E13: 在对应流程节点中配置AI 代码审查，自动完成检查代码提交。 | F13: 选择触发节点｜配置输入材料｜定义输出字段｜用样例验证 | G13: 参考提示词 | H13: 你是项目流程中的“检查代码提交”助手。请结合当前工作项、关联字段和附件完成以下任务：1. 按场景规则处理输入信息；2. 输出可直接写回项目的结构化结果；3. 标注判断依据和待人工确认项；4. 不补充材料中不存在的事实。场景要求：代码提交时，AI 节点自动检查是否关联了工作项、是否通过了 Code Review、是否包含必要的测试，不合规的提交自动拦截并通知开发者。 | M13: 复制参考提示词 | N13: 示例内容；上线前需校验字段、权限、触发条件和人工复核机制。 | O13: 检查代码提交 | P13: 模拟待校准
... A32: R051 | B32: S037 | C32: A033 | D32: 是 | E32: 在对应流程节点中配置AI 资格审核，自动完成审核报名资格。 | F32: 选择触发节点｜配置输入材料｜定义输出字段｜用样例验证 | G32: 参考提示词 | H32: 你是项目流程中的“审核报名资格”助手。请结合当前工作项、关联字段和附件完成以下任务：1. 按场景规则处理输入信息；2. 输出可直接写回项目的结构化结果；3. 标注判断依据和待人工确认项；4. 不补充材料中不存在的事实。场景要求：学科赛事报名时，AI 节点自动审核参赛资格：年级、学科、往届成绩等，不符合条件的自动驳回并说明原因。 | M32: 复制参考提示词 | N32: 示例内容；上线前需校验字段、权限、触发条件和人工复核机制。 | O32: 审核报名资格 | P32: 模拟待校准
A33: R015 | B33: S013 | C33: P002 | D33: 是 | E33: 通过 ITSM·工单通完成内外系统闭环。 | F33: 定义字段映射｜配置建单规则｜配置状态同步｜联调回传 | G33: PRD | I33: # 外部工单接入项目闭环 > 示例 PRD，用于说明复刻范围；实施前需结合目标工单系统 API、字段权限和状态模型校准。 ## 1. 背景与目标 客服或 IT 服务台中的外部工单与项目执行系统分离，人工转录容易遗漏上下文，处理状态也无法及时回传。插件需要把符合条件的外部工单自动创建为飞书项目工作项，并持续同步关键状态和处理结果。 ## 2. 用户与使用场景 - 客服运营：希望将需要研发处理的工单一键升级为项目任务。 - 项目经理：希望在项目内统一查看负责人、优先级和处理进度。 - 研发人员：希望直接获得问题描述、附件和客户影响范围。 ## 3. 功能范围 ### 3.1 工单转项目任务 - 支持按工单类型、优先级或人工操作触发建单。 - 映射标题、描述、客户、优先级、附件、来源链接等字段。 - 保存外部工单 ID，避免重复创建。 ### 3.2 双向状态同步 - 外部工单升级后，将项目状态、负责人和处理结论回传。 - 对无法映射的状态保留原值，并记录同步日志。 - 同步失败时自动重试，并向管理员发送告警。 ### 3.3 权限与审计 - 仅同步当前连接身份有权访问的数据。 - 敏感字段支持配置为不同步或脱敏。 - 记录建单、更新、失败和人工重试事件。 ## 4. 核心流程 1. 外部工单达到触发条件。 2. 插件读取工单详情并校验必填字段。 3. 根据映射规则创建或更新项目工作项。 4. 写回项目工作项链接和同步状态。 5. 后续状态变化通过事件触发双向同步。 ## 5. 字段映射 - 工单标题 → 工作项标题 - 问题描述 → 工作项描述 - 客户与影响范围 → 客户信息、影响范围字段 - 紧急程度 → 优先级 - 工单处理人 → 工作项负责人 - 附件与原始链接 → 附件、来源链接 ## 6. 异常处理 - 必填字段缺失：停止建单并提示补全。 - 重复工单：更新已有工作项，不重复创建。 - 用户匹配失败：保留原处理人文本并进入待分配队列。 - API 限流或超时：指数退避重试，超过阈值后告警。 ## 7. 验收标准 - 同一外部工单不会生成多个项目工作项。 - 字段映射结果与配置一致，附件和来源链接可访问。 - 项目状态变化可在约定时间内回传外部系统。 - 同步失败有明确日志、错误原因和人工重试入口。 - 无权限用户无法通过插件读取敏感工单内容。 | M33: 下载 PRD | N33: 示例说明；请根据真实字段、权限、流程状态和产品能力调整。 | O33: 工单集成方案 | P33: 模拟待校准
A34: R016 | B34: S014 | C34: P007 | D34: 是 | E34: 接入 GitLab 并按任务编号自动关联代码活动。 | F34: 授权代码仓库｜配置编号规则｜设置状态流转｜验证事件 | G34: PRD | I34: # 代码提交关联研发任务 > 示例 PRD，用于说明复刻范围；实施前需根据代码平台事件、分支规范和研发流程校准。 ## 1. 背景与目标 代码分支、提交和合并请求与研发任务依赖人工关联，项目状态无法反映真实开发进展。插件需要识别代码活动中的任务编号，自动建立关联，并按规则更新研发任务状态。 ## 2. 用户与使用场景 - 研发人员：在正常提交代码时自动关联任务，减少重复操作。 - 项目经理：查看任务即可了解分支、提交和合并请求进展。 - 测试人员：在代码合并后及时获得可提测信号。 ## 3. 功能范围 ### 3.1 任务编号识别 - 从分支名、提交信息和合并请求标题中识别任务编号。 - 支持配置编号正则、项目空间和工作项类型。 - 一个代码活动可关联多个任务，并提示异常编号。 ### 3.2 代码活动回写 - 将仓库、分支、提交、合并请求和流水线链接写入任务。 - 展示提交人、发生时间、当前状态和最新结果。 - 对已存在的关联进行幂等更新。 ### 3.3 自动状态流转 - 创建分支后，可将任务更新为“开发中”。 - 合并请求创建后，可更新为“待评审”。 - 合并且流水线通过后，可更新为“待测试”。 - 所有状态规则均可关闭或按项目单独配置。 ## 4. 核心流程 1. 代码平台发送 Push、Merge Request 或 Pipeline 事件。 2. 插件校验签名并解析任务编号。 3. 查询目标工作项及当前状态。 4. 写入代码活动，并按规则决定是否流转状态。 5. 保存处理结果，失败事件进入重试队列。 ## 5. 配置项 - 代码平台地址、仓库范围和访问凭证 - 任务编号识别规则 - 事件类型与状态流转映射 - 是否允许跨项目关联 - 机器人评论模板与通知对象 ## 6. 异常处理 - 未识别任务编号：记录事件但不更新工作项。 - 工作项不存在或无权限：标记失败并通知提交人。 - 状态不满足流转条件：只写入代码活动，不强制改状态。 - 重复事件：按事件 ID 幂等处理。 - Webhook 验签失败：拒绝请求并记录安全日志。 ## 7. 验收标准 - 符合规则的分支、提交和合并请求能正确关联任务。 - 重复事件不会产生重复关联或重复评论。 - 状态流转严格遵循配置，不覆盖人工终态。 - 失败事件可查询、重试，并显示明确错误原因。 - 访问凭证加密存储，Webhook 请求完成签名校验。 | M34: 下载 PRD | N34: 示例说明；请根据真实字段、权限、流程状态和产品能力调整。 | O34: 研发集成方案 | P34: 模拟待校准
A35: R017 | B35: S015 | C35: L001 | D35: 是 | E35: 用轻应用搭建一页式管理驾驶舱。 | F35: 确定指标｜连接数据源｜搭建页面｜配置权限｜发布 | G35: 搭建说明 | M35: 查看搭建说明 | N35: 示例说明；请根据真实字段、权限、流程状态和产品能力调整。 | O35: 管理驾驶舱 | P35: 模拟待校准
A36: R018 | B36: S016 | C36: L002 | D36: 是 | E36: 用轻应用连接会议议题、项目数据和决议。 | F36: 设计议题结构｜连接项目数据｜配置会后任务｜发布入口 | G36: 搭建说明 | M36: 查看搭建说明 | N36: 示例说明；请根据真实字段、权限、流程状态和产品能力调整。 | O36: 会议联动汇报台 | P36: 模拟待校准
A37: R019 | B37: S017 | C37: T002 | D37: 是 | E37: 复制软件研发管理模板并按团队流程完成初始化。 | F37: 打开模板｜复制到空间｜调整流程字段｜配置权限｜导入项目 | G37: 直接链接 | M37: 使用模板 | N37: 示例说明；请根据真实字段、权限、流程状态和产品能力调整。 | O37: 可运行的研发空间 | P37: 模拟待校准
A38: R020 | B38: S018 | C38: O004 | D38: 是 | E38: 查看 ASPICE 汽车软件研发方案并结合组织现状规划实施。 | F38: 查看方案范围｜评估现状差距｜确定实施阶段｜启动方案设计 | G38: 直接链接 | M38: 查看解决方案 | N38: 示例说明；请根据真实字段、权限、流程状态和产品能力调整。 | O38: 解决方案实施蓝图 | P38: 模拟待校准
A39: R052 | B39: S038 | C39: A011 | D39: 是 | E39: 在对应流程节点中配置AI 生成云文档，自动完成撰写产品 PRD。 | F39: 选择需求节点｜关联背景材料｜配置 PRD 模板｜生成并人工确认 | G39: 参考提示词 | H39: 你是产品需求文档助手。请结合当前需求、访谈记录、会议纪要和关联资料，按照“背景与问题、目标与指标、用户与场景、功能范围、用户故事、方案说明、验收标准、风险与待确认项”的结构生成 PRD 初稿。仅使用已有材料，不明确的信息标记为“待确认”，不要虚构数据或结论。 | M39: 复制参考提示词 | N39: 示例内容；上线前需校验字段、权限、触发条件和人工复核机制。 | O39: 结构化 PRD 初稿 | P39: 模拟待校准
A40: R053 | B40: S039 | C40: A001 | D40: 是 | E40: 在对应流程节点中配置自定义指令，自动完成走查产品需求。 | F40: 配置走查清单｜关联 PRD 与原型｜执行需求检查｜确认修改建议 | G40: 参考提示词 | H40: 你是资深产品经理，请在需求提交正式评审前完成 PM 走查。检查：1. 背景、目标和成功指标是否明确；2. 用户角色与核心场景是否完整；3. 功能范围和非目标是否清晰；4. 主流程、异常流程和权限逻辑是否闭环；5. 验收标准是否具体可验证。按“问题位置、问题描述、影响、修改建议、严重程度”输出，不替作者补写未经确认的业务事实。 | M40: 复制参考提示词 | N40: 示例内容；上线前需校验字段、权限、触发条件和人工复核机制。 | O40: 需求走查问题清单 | P40: 模拟待校准
A41: R054 | B41: S040 | C41: A005 | D41: 是 | E41: 在对应流程节点中配置内容总结，自动完成总结项目成果。 | F41: 选择结项节点｜汇总项目数据｜配置总结结构｜生成并确认 | G41: 参考提示词 | H41: 你是项目总结助手。请结合项目目标、里程碑、交付物、风险记录、变更记录和关键决策，生成项目总结。结构包括：目标达成情况、关键成果、未完成事项、主要问题与处理、有效做法、经验教训、后续行动。每项结论注明依据；无法从材料确认的内容标记“待补充”，不要夸大成果。 | M41: 复制参考提示词 | N41: 示例内容；上线前需校验字段、权限、触发条件和人工复核机制。 | O41: 项目总结初稿 | P41: 模拟待校准
A42: R055 | B42: S041 | C42: A011 | D42: 是 | E42: 在对应流程节点中配置AI 生成云文档，自动完成撰写产品手册。 | F42: 选择发布节点｜关联版本材料｜配置手册目录｜生成并人工校对 | G42: 参考提示词 | H42: 你是产品文档助手。请结合当前版本的需求说明、功能描述、操作步骤、权限规则和常见问题，按照“产品概述、适用对象、功能说明、操作指引、权限与限制、常见问题、版本信息”的结构生成产品手册初稿。使用面向最终用户的语言；缺失截图或无法确认的信息标记为“待补充”。 | M42: 复制参考提示词 | N42: 示例内容；上线前需校验字段、权限、触发条件和人工复核机制。 | O42: 产品手册初稿 | P42: 模拟待校准

Sheet 字段说明
A1: 工作表 | B1: 字段 | C1: 必填 | D1: 填写说明
A2: 场景表 | B2: 场景ID | C2: 是 | D2: 唯一且稳定，建议 S001 起，不随标题变化。
A3: 场景表 | B3: 卡片短描述 | C3: 是 | D3: 建议 40～70 字，说明发生什么，不写产品功能堆砌。
A4: 场景表 | B4: 问题描述 | C4: 是 | D4: 详情页场景背景，解释用户为什么需要这个实践。
A5: 场景表 | B5: 场景说明 | C5: 是 | D5: 详情页左栏，解释流程如何运转，不写按钮说明。
A6: 场景表 | B6: 预期价值 | C6: 是 | D6: 多个价值使用 ｜ 分隔。
A7: 场景表 | B7: 封面类型 | C7: 是 | D7: 流程节点或图片。
A8: 产品表 | B8: 产品名称 | C8: 是 | D8: 使用真实发布名称，禁止用场景名替代产品名。
A9: 产品表 | B9: 目录是否展示 | C9: 是 | D9: 轻应用必须为否，其余按实际情况。
A10: 产品表 | B10: 来源URL | C10: 核实内容必填 | D10: 记录名称、描述或案例的公开来源，方便复核。
A11: 关系表 | B11: 使用方法概述 | C11: 是 | D11: 推荐详情右栏的使用方法摘要。
A12: 关系表 | B12: 操作步骤 | C12: 是 | D12: 按顺序填写，步骤间使用 ｜ 分隔。
... A15: 场景表 | B15: 工作目标 | C15: 好方法必填 | D15: 按用户要完成的工作分类，不按 AI 应用、插件或轻应用等产品类型分类。

Sheet 枚举与规范
A1: 枚举名称 | B1: 可选值 | C1: 备注
A2: 产品类型 | B2: AI应用｜插件｜轻应用｜模板｜解决方案 | C2: 轻应用只在推荐出现
A3: 产品子类型 | B3: AI节点｜AI字段 | C3: 官网当前精选 AI 应用按 AI 节点与 AI 字段展示
A4: 封面类型 | B4: 流程节点｜图片
A5: 是否 | B5: 是｜否
A6: 内容状态 | B6: 模拟待校准｜草稿｜可发布 | C6: 只有核实后的内容才设为可发布
A7: 交付类型 | B7: 参考提示词｜PRD｜搭建说明｜直接链接
A8: 行业 | B8: 互联网｜汽车｜消费电子｜制造｜金融｜游戏｜教育｜医疗｜零售｜能源
A9: 角色 | B9: 产品经理｜项目经理｜研发｜测试｜设计｜运营｜销售｜高管
A10: 工作目标 | B10: 信息提取与补全｜内容撰写与总结｜计划拆解与协同｜分类分派与流转｜质量检查与审核｜分析评估与预警 | C10: 用于第二套方案“好方法”的用户侧分类。

Sheet 数据检查
A1: 检查项 | B1: 结果 | C1: 说明
A2: 场景数量 | B2: =COUNTA(场景表!A:A)-1 | C2: 推荐演示建议 18 条
A3: 产品数量 | B3: =COUNTA(产品表!A:A)-1 | C3: 含仅推荐出现的轻应用
A4: 关系数量 | B4: =COUNTA(场景产品关系表!A:A)-1 | C4: 每个推荐场景至少一条关系
A5: 未关联场景数 | B5: =COUNTIF(场景产品关系表!B:B,"")-1 | C5: 应为 0；空白预留行不计入实际导入
A6: 可发布场景数 | B6: =COUNTIF(场景表!P:P,"可发布") | C6: 上线前逐条核实后更新
A7: 可发布产品数 | B7: =COUNTIF(产品表!T:T,"可发布") | C7: 上线前逐条核实后更新

Sheet 录入字典
A1: 场景ID | B1: 场景名称 | C1: AI应用ID | D1: AI应用名称
A2: S001 | B2: 补全客户信息 | C2: A001 | D2: 自定义指令
A3: S002 | B3: 拆解会议任务 | C3: A002 | D3: 智能打分
A4: S003 | B4: 创建外部工单 | C4: A003 | D4: 分类打标
A5: S004 | B5: 创建邮件任务 | C5: A004 | D5: 关键内容提取
A6: S005 | B6: 提取合同条款 | C6: A005 | D6: 内容总结
A7: S006 | B7: 分类客户反馈 | C7: A006 | D7: 智能翻译
A8: S007 | B8: 分派研发需求 | C8: A007 | D8: AI 智能洞察
A9: S008 | B9: 评定缺陷等级 | C9: A008 | D9: AI 智能填单
A10: S009 | B10: 分流客服工单 | C10: A009 | D10: 智能测试用例生成
A11: S010 | B11: 检查交付质量 | C11: A010 | D11: 智能体连接器
A12: S011 | B12: 检查需求合规 | C12: A011 | D12: AI 生成云文档
... A34: S014 | B34: 代码提交关联研发任务 | C34: A033 | D34: AI 资格审核
A35: S015 | B35: 管理驾驶舱快速搭建
A36: S016 | B36: 会议联动项目汇报
A37: S017 | B37: 软件研发流程快速启用
A38: S018 | B38: 整车研发跨域协同
A39: S038 | B39: 撰写产品 PRD
A40: S039 | B40: 走查产品需求
A41: S040 | B41: 总结项目成果
A42: S041 | B42: 撰写产品手册
